Workbook

Sheet Rekap All 2026
B1: PT NOBI PUTRA ANGKASA
B2: REKAPITULASI PEMBAYARAN BIAYA SDM | AS2: (F7+J7+N7+R7+V7+Z7+AD7+AH7+AL7+AP7+AT7+AX7)
B3: TAHUN 2026
B5: No. | C5: Uraian | D5: Januari | H5: Februari | L5: Maret | P5: April | T5: Mei | X5: Juni | AB5: Juli | AF5: Agustus | AJ5: September | AN5: Oktober | AR5: Nopember | AV5: Desember | BC5: 2025
D6: Jml Kary. | E6: Nilai | F6: % JK | G6: % GJ | H6: Jml Kary. | I6: Nilai | J6: % JK | K6: % GJ | L6: Jml Kary. | M6: Nilai | N6: % JK | O6: % GJ | P6: Jml Kary. | Q6: Nilai | R6: % JK | S6: % GJ | T6: Jml Kary. | U6: Nilai | V6: % JK | W6: % GJ | X6: Jml Kary. | Y6: Nilai | Z6: % JK | AA6: % GJ | AB6: Jml Kary. | AC6: Nilai | AD6: % JK | AE6: % GJ | AF6: Jml Kary. | AG6: Nilai | AH6: % JK | AI6: % GJ | AJ6: Jml Kary. | AK6: Nilai | AL6: % JK | AM6: % GJ | AN6: Jml Kary. | AO6: Nilai | AP6: % JK | AQ6: % GJ | AR6: Jml Kary. | AS6: Nilai | AT6: % JK | AU6: % GJ | AV6: Jml Kary. | AW6: Nilai | AX6: % JK | AY6: % GJ | AZ6: TOTAL | BA6: % JK | BB6: % GJ | BC6: Jan - Mar | BD6: Apr - Jun | BE6: Jul - Sept | BF6: Okt - Des
B7: 1 | C7: None | D7: =NPA!D7+NES!D7+'2026-PKL NPA'!D7+'2026- Harian NES'!D7+'2026-Harian NPA'!D7+'2026-LPK MKS NPA'!D7+'2026-LPK MKM NPA'!D7+'2026-LPK DKP NPA '!D7+'2026-LPK CTPS NPA'!D7+'2026-LPK CDB NPA'!D7+'2026-OS CTPS NPA'!D7+'2026-OS CDB NPA'!D7 -> 2 | E7: =NPA!E7+NES!E7+'2026-PKL NPA'!E7+'2026- Harian NES'!E7+'2026-Harian NPA'!E7+'2026-LPK MKS NPA'!E7+'2026-LPK MKM NPA'!E7+'2026-LPK DKP NPA '!E7+'2026-LPK CTPS NPA'!E7+'2026-LPK CDB NPA'!E7+'2026-OS CTPS NPA'!E7+'2026-OS CDB NPA'!E7 -> 105169321 | F7: =D7/$D$24 -> 0.0061538462 | G7: =E7/$E$24 -> 0.042106956 | H7: =NPA!H7+NES!H7+'2026-PKL NPA'!H7+'2026- Harian NES'!H7+'2026-Harian NPA'!H7+'2026-LPK MKS NPA'!H7+'2026-LPK MKM NPA'!H7+'2026-LPK DKP NPA '!H7+'2026-LPK CTPS NPA'!H7+'2026-LPK CDB NPA'!H7+'2026-OS CTPS NPA'!H7+'2026-OS CDB NPA'!H7 -> 2 | I7: 75504329 | J7: =H7/$H$24 -> 0.0064308682 | K7: =I7/$I$24 -> 0.032432181 | L7: =NPA!L7+NES!L7+'2026-PKL NPA'!L7+'2026- Harian NES'!L7+'2026-Harian NPA'!L7+'2026-LPK MKS NPA'!L7+'2026-LPK MKM NPA'!L7+'2026-LPK DKP NPA '!L7+'2026-LPK CTPS NPA'!L7+'2026-LPK CDB NPA'!L7+'2026-OS CTPS NPA'!L7+'2026-OS CDB NPA'!L7 -> 2 | M7: =NPA!M7+NES!M7+'2026-PKL NPA'!M7+'2026- Harian NES'!M7+'2026-Harian NPA'!M7+'2026-LPK MKS NPA'!M7+'2026-LPK MKM NPA'!M7+'2026-LPK DKP NPA '!M7+'2026-LPK CTPS NPA'!M7+'2026-LPK CDB NPA'!M7+'2026-OS CTPS NPA'!M7+'2026-OS CDB NPA'!M7 -> 74124788 | N7: =L7/$L$24 -> 0.0064308682 | O7: =M7/$M$24 -> 0.034178902 | P7: =NPA!P7+NES!P7+'2026-PKL NPA'!P7+'2026- Harian NES'!P7+'2026-Harian NPA'!P7+'2026-LPK MKS NPA'!P7+'2026-LPK MKM NPA'!P7+'2026-LPK DKP NPA '!P7+'2026-LPK CTPS NPA'!P7+'2026-LPK CDB NPA'!P7+'2026-OS CTPS NPA'!P7+'2026-OS CDB NPA'!P7 -> 0 | Q7: =NPA!Q7+NES!Q7+'2026-PKL NPA'!Q7+'2026- Harian NES'!Q7+'2026-Harian NPA'!Q7+'2026-LPK MKS NPA'!Q7+'2026-LPK MKM NPA'!Q7+'2026-LPK DKP NPA '!Q7+'2026-LPK CTPS NPA'!Q7+'2026-LPK CDB NPA'!Q7+'2026-OS CTPS NPA'!Q7+'2026-OS CDB NPA'!Q7 -> 0 | R7: =P7/$P$24 -> #DIV/0! | S7: =Q7/$Q$24 -> #DIV/0! | T7: =NPA!T7+NES!T7+'2026-PKL NPA'!T7+'2026- Harian NES'!T7+'2026-Harian NPA'!T7+'2026-LPK MKS NPA'!T7+'2026-LPK MKM NPA'!T7+'2026-LPK DKP NPA '!T7+'2026-LPK CTPS NPA'!T7+'2026-LPK CDB NPA'!T7+'2026-OS CTPS NPA'!T7+'2026-OS CDB NPA'!T7 -> 0 | U7: =NPA!U7+NES!U7+'2026-PKL NPA'!U7+'2026- Harian NES'!U7+'2026-Harian NPA'!U7+'2026-LPK MKS NPA'!U7+'2026-LPK MKM NPA'!U7+'2026-LPK DKP NPA '!U7+'2026-LPK CTPS NPA'!U7+'2026-LPK CDB NPA'!U7+'2026-OS CTPS NPA'!U7+'2026-OS CDB NPA'!U7 -> 0 | V7: =T7/$T$24 -> #DIV/0! | W7: =U7/$U$24 -> #DIV/0! | X7: =NPA!X7+NES!X7+'2026-PKL NPA'!X7+'2026- Harian NES'!X7+'2026-Harian NPA'!X7+'2026-LPK MKS NPA'!X7+'2026-LPK MKM NPA'!X7+'2026-LPK DKP NPA '!X7+'2026-LPK CTPS NPA'!X7+'2026-LPK CDB NPA'!X7+'2026-OS CTPS NPA'!X7+'2026-OS CDB NPA'!X7 -> 0 | Y7: =NPA!Y7+NES!Y7+'2026-PKL NPA'!Y7+'2026- Harian NES'!Y7+'2026-Harian NPA'!Y7+'2026-LPK MKS NPA'!Y7+'2026-LPK MKM NPA'!Y7+'2026-LPK DKP NPA '!Y7+'2026-LPK CTPS NPA'!Y7+'2026-LPK CDB NPA'!Y7+'2026-OS CTPS NPA'!Y7+'2026-OS CDB NPA'!Y7 -> 0 | Z7: =X7/$X$24 -> #DIV/0! | AA7: =Y7/$Y$24 -> #DIV/0! | AB7: =NPA!AB7+NES!AB7+'2026-PKL NPA'!AB7+'2026- Harian NES'!AB7+'2026-Harian NPA'!AB7+'2026-LPK MKS NPA'!AB7+'2026-LPK MKM NPA'!AB7+'2026-LPK DKP NPA '!AB7+'2026-LPK CTPS NPA'!AB7+'2026-LPK CDB NPA'!AB7+'2026-OS CTPS NPA'!AB7+'2026-OS CDB NPA'!AB7 -> 0 | AC7: =NPA!AC7+NES!AC7+'2026-PKL NPA'!AC7+'2026- Harian NES'!AC7+'2026-Harian NPA'!AC7+'2026-LPK MKS NPA'!AC7+'2026-LPK MKM NPA'!AC7+'2026-LPK DKP NPA '!AC7+'2026-LPK CTPS NPA'!AC7+'2026-LPK CDB NPA'!AC7+'2026-OS CTPS NPA'!AC7+'2026-OS CDB NPA'!AC7 -> 0 | AD7: =AB7/$AB$24 -> #DIV/0! | AE7: =AC7/$AC$24 -> #DIV/0! | AF7: =NPA!AF7+NES!AF7+'2026-PKL NPA'!AF7+'2026- Harian NES'!AF7+'2026-Harian NPA'!AF7+'2026-LPK MKS NPA'!AF7+'2026-LPK MKM NPA'!AF7+'2026-LPK DKP NPA '!AF7+'2026-LPK CTPS NPA'!AF7+'2026-LPK CDB NPA'!AF7+'2026-OS CTPS NPA'!AF7+'2026-OS CDB NPA'!AF7 -> 0 | AG7: =NPA!AG7+NES!AG7+'2026-PKL NPA'!AG7+'2026- Harian NES'!AG7+'2026-Harian NPA'!AG7+'2026-LPK MKS NPA'!AG7+'2026-LPK MKM NPA'!AG7+'2026-LPK DKP NPA '!AG7+'2026-LPK CTPS NPA'!AG7+'2026-LPK CDB NPA'!AG7+'2026-OS CTPS NPA'!AG7+'2026-OS CDB NPA'!AG7 -> 0 | AH7: =AF7/$AF$24 -> #DIV/0! | AI7: =AG7/$AG$24 -> #DIV/0! | AJ7: =NPA!AJ7+NES!AJ7+'2026-PKL NPA'!AJ7+'2026- Harian NES'!AJ7+'2026-Harian NPA'!AJ7+'2026-LPK MKS NPA'!AJ7+'2026-LPK MKM NPA'!AJ7+'2026-LPK DKP NPA '!AJ7+'2026-LPK CTPS NPA'!AJ7+'2026-LPK CDB NPA'!AJ7+'2026-OS CTPS NPA'!AJ7+'2026-OS CDB NPA'!AJ7 -> 0 | AK7: =NPA!AK7+NES!AK7+'2026-PKL NPA'!AK7+'2026- Harian NES'!AK7+'2026-Harian NPA'!AK7+'2026-LPK MKS NPA'!AK7+'2026-LPK MKM NPA'!AK7+'2026-LPK DKP NPA '!AK7+'2026-LPK CTPS NPA'!AK7+'2026-LPK CDB NPA'!AK7+'2026-OS CTPS NPA'!AK7+'2026-OS CDB NPA'!AK7 -> 0 | AL7: =AJ7/$AJ$24 -> #DIV/0! | AM7: =AK7/$AK$24 -> #DIV/0! | AN7: =NPA!AN7+NES!AN7+'2026-PKL NPA'!AN7+'2026- Harian NES'!AN7+'2026-Harian NPA'!AN7+'2026-LPK MKS NPA'!AN7+'2026-LPK MKM NPA'!AN7+'2026-LPK DKP NPA '!AN7+'2026-LPK CTPS NPA'!AN7+'2026-LPK CDB NPA'!AN7+'2026-OS CTPS NPA'!AN7+'2026-OS CDB NPA'!AN7 -> 0 | AO7: =NPA!AO7+NES!AO7+'2026-PKL NPA'!AO7+'2026- Harian NES'!AO7+'2026-Harian NPA'!AO7+'2026-LPK MKS NPA'!AO7+'2026-LPK MKM NPA'!AO7+'2026-LPK DKP NPA '!AO7+'2026-LPK CTPS NPA'!AO7+'2026-LPK CDB NPA'!AO7+'2026-OS CTPS NPA'!AO7+'2026-OS CDB NPA'!AO7 -> 0 | AP7: =AN7/$AN$24 -> #DIV/0! | AQ7: =AO7/$AO$24 -> #DIV/0! | AR7: =NPA!AR7+NES!AR7+'2026-PKL NPA'!AR7+'2026- Harian NES'!AR7+'2026-Harian NPA'!AR7+'2026-LPK MKS NPA'!AR7+'2026-LPK MKM NPA'!AR7+'2026-LPK DKP NPA '!AR7+'2026-LPK CTPS NPA'!AR7+'2026-LPK CDB NPA'!AR7+'2026-OS CTPS NPA'!AR7+'2026-OS CDB NPA'!AR7 -> 0 | AS7: =NPA!AS7+NES!AS7+'2026-PKL NPA'!AS7+'2026- Harian NES'!AS7+'2026-Harian NPA'!AS7+'2026-LPK MKS NPA'!AS7+'2026-LPK MKM NPA'!AS7+'2026-LPK DKP NPA '!AS7+'2026-LPK CTPS NPA'!AS7+'2026-LPK CDB NPA'!AS7+'2026-OS CTPS NPA'!AS7+'2026-OS CDB NPA'!AS7 -> 0 | AT7: =AR7/$AR$24 -> #DIV/0! | AU7: =AS7/$AS$24 -> #DIV/0! | AV7: =NPA!AV7+NES!AV7+'2026-PKL NPA'!AV7+'2026- Harian NES'!AV7+'2026-Harian NPA'!AV7+'2026-LPK MKS NPA'!AV7+'2026-LPK MKM NPA'!AV7+'2026-LPK DKP NPA '!AV7+'2026-LPK CTPS NPA'!AV7+'2026-LPK CDB NPA'!AV7+'2026-OS CTPS NPA'!AV7+'2026-OS CDB NPA'!AV7 -> 0 | AW7: =NPA!AW7+NES!AW7+'2026-PKL NPA'!AW7+'2026- Harian NES'!AW7+'2026-Harian NPA'!AW7+'2026-LPK MKS NPA'!AW7+'2026-LPK MKM NPA'!AW7+'2026-LPK DKP NPA '!AW7+'2026-LPK CTPS NPA'!AW7+'2026-LPK CDB NPA'!AW7+'2026-OS CTPS NPA'!AW7+'2026-OS CDB NPA'!AW7 -> 0 | AX7: =AV7/$AJ$24 -> #DIV/0! | AY7: =AW7/$AK$24 -> #DIV/0! | AZ7: =E7+I7+M7+Q7+U7+Y7+AC7+AG7+AK7+AO7+AS7+AW7 -> 254798438 | BA7: =AVERAGE(F7,J7,N7,R7,V7,Z7,AD7,AH7,AL7,AP7,AT7,AX7) -> #DIV/0! | BB7: =AVERAGE(G7,K7,O7,S7,W7,AA7,AE7,AI7,AM7,AQ7,AU7,AY7) -> #DIV/0! | BC7: =E7+I7+M7 -> 254798438 | BD7: =Q7+U7+Y7 -> 0 | BE7: =AC7+AG7+AK7 -> 0 | BF7: =AO7+AS7+AW7 -> 0
B8: =B7+1 -> 2 | C8: Keuangan & Akunting | D8: =NPA!D8+NES!D8+'2026-PKL NPA'!D8+'2026- Harian NES'!D8+'2026-Harian NPA'!D8+'2026-LPK MKS NPA'!D8+'2026-LPK MKM NPA'!D8+'2026-LPK DKP NPA '!D8+'2026-LPK CTPS NPA'!D8+'2026-LPK CDB NPA'!D8+'2026-OS CTPS NPA'!D8+'2026-OS CDB NPA'!D8 -> 10 | E8: =NPA!E8+NES!E8+'2026-PKL NPA'!E8+'2026- Harian NES'!E8+'2026-Harian NPA'!E8+'2026-LPK MKS NPA'!E8+'2026-LPK MKM NPA'!E8+'2026-LPK DKP NPA '!E8+'2026-LPK CTPS NPA'!E8+'2026-LPK CDB NPA'!E8+'2026-OS CTPS NPA'!E8+'2026-OS CDB NPA'!E8 -> 124852645 | F8: =D8/$D$24 -> 0.030769231 | G8: =E8/$E$24 -> 0.049987627 | H8: =NPA!H8+NES!H8+'2026-PKL NPA'!H8+'2026- Harian NES'!H8+'2026-Harian NPA'!H8+'2026-LPK MKS NPA'!H8+'2026-LPK MKM NPA'!H8+'2026-LPK DKP NPA '!H8+'2026-LPK CTPS NPA'!H8+'2026-LPK CDB NPA'!H8+'2026-OS CTPS NPA'!H8+'2026-OS CDB NPA'!H8 -> 10 | I8: =NPA!I8+NES!I8+'2026-PKL NPA'!I8+'2026- Harian NES'!I8+'2026-Harian NPA'!I8+'2026-LPK MKS NPA'!I8+'2026-LPK MKM NPA'!I8+'2026-LPK DKP NPA '!I8+'2026-LPK CTPS NPA'!I8+'2026-LPK CDB NPA'!I8+'2026-OS CTPS NPA'!I8+'2026-OS CDB NPA'!I8 -> 115094497 | J8: =H8/$H$24 -> 0.032154341 | K8: =I8/$I$24 -> 0.049437768 | L8: =NPA!L8+NES!L8+'2026-PKL NPA'!L8+'2026- Harian NES'!L8+'2026-Harian NPA'!L8+'2026-LPK MKS NPA'!L8+'2026-LPK MKM NPA'!L8+'2026-LPK DKP NPA '!L8+'2026-LPK CTPS NPA'!L8+'2026-LPK CDB NPA'!L8+'2026-OS CTPS NPA'!L8+'2026-OS CDB NPA'!L8 -> 10 | M8: =NPA!M8+NES!M8+'2026-PKL NPA'!M8+'2026- Harian NES'!M8+'2026-Harian NPA'!M8+'2026-LPK MKS NPA'!M8+'2026-LPK MKM NPA'!M8+'2026-LPK DKP NPA '!M8+'2026-LPK CTPS NPA'!M8+'2026-LPK CDB NPA'!M8+'2026-OS CTPS NPA'!M8+'2026-OS CDB NPA'!M8 -> 110226902 | N8: =L8/$L$24 -> 0.032154341 | O8: =M8/$M$24 -> 0.050825569 | P8: =NPA!P8+NES!P8+'2026-PKL NPA'!P8+'2026- Harian NES'!P8+'2026-Harian NPA'!P8+'2026-LPK MKS NPA'!P8+'2026-LPK MKM NPA'!P8+'2026-LPK DKP NPA '!P8+'2026-LPK CTPS NPA'!P8+'2026-LPK CDB NPA'!P8+'2026-OS CTPS NPA'!P8+'2026-OS CDB NPA'!P8 -> 0 | Q8: =NPA!Q8+NES!Q8+'2026-PKL NPA'!Q8+'2026- Harian NES'!Q8+'2026-Harian NPA'!Q8+'2026-LPK MKS NPA'!Q8+'2026-LPK MKM NPA'!Q8+'2026-LPK DKP NPA '!Q8+'2026-LPK CTPS NPA'!Q8+'2026-LPK CDB NPA'!Q8+'2026-OS CTPS NPA'!Q8+'2026-OS CDB NPA'!Q8 -> 0 | R8: =P8/$P$24 -> #DIV/0! | S8: =Q8/$Q$24 -> #DIV/0! | T8: =NPA!T8+NES!T8+'2026-PKL NPA'!T8+'2026- Harian NES'!T8+'2026-Harian NPA'!T8+'2026-LPK MKS NPA'!T8+'2026-LPK MKM NPA'!T8+'2026-LPK DKP NPA '!T8+'2026-LPK CTPS NPA'!T8+'2026-LPK CDB NPA'!T8+'2026-OS CTPS NPA'!T8+'2026-OS CDB NPA'!T8 -> 0 | U8: =NPA!U8+NES!U8+'2026-PKL NPA'!U8+'2026- Harian NES'!U8+'2026-Harian NPA'!U8+'2026-LPK MKS NPA'!U8+'2026-LPK MKM NPA'!U8+'2026-LPK DKP NPA '!U8+'2026-LPK CTPS NPA'!U8+'2026-LPK CDB NPA'!U8+'2026-OS CTPS NPA'!U8+'2026-OS CDB NPA'!U8 -> 0 | V8: =T8/$T$24 -> #DIV/0! | W8: =U8/$U$24 -> #DIV/0! | X8: =NPA!X8+NES!X8+'2026-PKL NPA'!X8+'2026- Harian NES'!X8+'2026-Harian NPA'!X8+'2026-LPK MKS NPA'!X8+'2026-LPK MKM NPA'!X8+'2026-LPK DKP NPA '!X8+'2026-LPK CTPS NPA'!X8+'2026-LPK CDB NPA'!X8+'2026-OS CTPS NPA'!X8+'2026-OS CDB NPA'!X8 -> 0 | Y8: =NPA!Y8+NES!Y8+'2026-PKL NPA'!Y8+'2026- Harian NES'!Y8+'2026-Harian NPA'!Y8+'2026-LPK MKS NPA'!Y8+'2026-LPK MKM NPA'!Y8+'2026-LPK DKP NPA '!Y8+'2026-LPK CTPS NPA'!Y8+'2026-LPK CDB NPA'!Y8+'2026-OS CTPS NPA'!Y8+'2026-OS CDB NPA'!Y8 -> 0 | Z8: =X8/$X$24 -> #DIV/0! | AA8: =Y8/$Y$24 -> #DIV/0! | AB8: =NPA!AB8+NES!AB8+'2026-PKL NPA'!AB8+'2026- Harian NES'!AB8+'2026-Harian NPA'!AB8+'2026-LPK MKS NPA'!AB8+'2026-LPK MKM NPA'!AB8+'2026-LPK DKP NPA '!AB8+'2026-LPK CTPS NPA'!AB8+'2026-LPK CDB NPA'!AB8+'2026-OS CTPS NPA'!AB8+'2026-OS CDB NPA'!AB8 -> 0 | AC8: =NPA!AC8+NES!AC8+'2026-PKL NPA'!AC8+'2026- Harian NES'!AC8+'2026-Harian NPA'!AC8+'2026-LPK MKS NPA'!AC8+'2026-LPK MKM NPA'!AC8+'2026-LPK DKP NPA '!AC8+'2026-LPK CTPS NPA'!AC8+'2026-LPK CDB NPA'!AC8+'2026-OS CTPS NPA'!AC8+'2026-OS CDB NPA'!AC8 -> 0 | AD8: =AB8/$AB$24 -> #DIV/0! | AE8: =AC8/$AC$24 -> #DIV/0! | AF8: =NPA!AF8+NES!AF8+'2026-PKL NPA'!AF8+'2026- Harian NES'!AF8+'2026-Harian NPA'!AF8+'2026-LPK MKS NPA'!AF8+'2026-LPK MKM NPA'!AF8+'2026-LPK DKP NPA '!AF8+'2026-LPK CTPS NPA'!AF8+'2026-LPK CDB NPA'!AF8+'2026-OS CTPS NPA'!AF8+'2026-OS CDB NPA'!AF8 -> 0 | AG8: =NPA!AG8+NES!AG8+'2026-PKL NPA'!AG8+'2026- Harian NES'!AG8+'2026-Harian NPA'!AG8+'2026-LPK MKS NPA'!AG8+'2026-LPK MKM NPA'!AG8+'2026-LPK DKP NPA '!AG8+'2026-LPK CTPS NPA'!AG8+'2026-LPK CDB NPA'!AG8+'2026-OS CTPS NPA'!AG8+'2026-OS CDB NPA'!AG8 -> 0 | AH8: =AF8/$AF$24 -> #DIV/0! | AI8: =AG8/$AG$24 -> #DIV/0! | AJ8: =NPA!AJ8+NES!AJ8+'2026-PKL NPA'!AJ8+'2026- Harian NES'!AJ8+'2026-Harian NPA'!AJ8+'2026-LPK MKS NPA'!AJ8+'2026-LPK MKM NPA'!AJ8+'2026-LPK DKP NPA '!AJ8+'2026-LPK CTPS NPA'!AJ8+'2026-LPK CDB NPA'!AJ8+'2026-OS CTPS NPA'!AJ8+'2026-OS CDB NPA'!AJ8 -> 0 | AK8: =NPA!AK8+NES!AK8+'2026-PKL NPA'!AK8+'2026- Harian NES'!AK8+'2026-Harian NPA'!AK8+'2026-LPK MKS NPA'!AK8+'2026-LPK MKM NPA'!AK8+'2026-LPK DKP NPA '!AK8+'2026-LPK CTPS NPA'!AK8+'2026-LPK CDB NPA'!AK8+'2026-OS CTPS NPA'!AK8+'2026-OS CDB NPA'!AK8 -> 0 | AL8: =AJ8/$AJ$24 -> #DIV/0! | AM8: =AK8/$AK$24 -> #DIV/0! | AN8: =NPA!AN8+NES!AN8+'2026-PKL NPA'!AN8+'2026- Harian NES'!AN8+'2026-Harian NPA'!AN8+'2026-LPK MKS NPA'!AN8+'2026-LPK MKM NPA'!AN8+'2026-LPK DKP NPA '!AN8+'2026-LPK CTPS NPA'!AN8+'2026-LPK CDB NPA'!AN8+'2026-OS CTPS NPA'!AN8+'2026-OS CDB NPA'!AN8 -> 0 | AO8: =NPA!AO8+NES!AO8+'2026-PKL NPA'!AO8+'2026- Harian NES'!AO8+'2026-Harian NPA'!AO8+'2026-LPK MKS NPA'!AO8+'2026-LPK MKM NPA'!AO8+'2026-LPK DKP NPA '!AO8+'2026-LPK CTPS NPA'!AO8+'2026-LPK CDB NPA'!AO8+'2026-OS CTPS NPA'!AO8+'2026-OS CDB NPA'!AO8 -> 0 | AP8: =AN8/$AN$24 -> #DIV/0! | AQ8: =AO8/$AO$24 -> #DIV/0! | AR8: =NPA!AR8+NES!AR8+'2026-PKL NPA'!AR8+'2026- Harian NES'!AR8+'2026-Harian NPA'!AR8+'2026-LPK MKS NPA'!AR8+'2026-LPK MKM NPA'!AR8+'2026-LPK DKP NPA '!AR8+'2026-LPK CTPS NPA'!AR8+'2026-LPK CDB NPA'!AR8+'2026-OS CTPS NPA'!AR8+'2026-OS CDB NPA'!AR8 -> 0 | AS8: =NPA!AS8+NES!AS8+'2026-PKL NPA'!AS8+'2026- Harian NES'!AS8+'2026-Harian NPA'!AS8+'2026-LPK MKS NPA'!AS8+'2026-LPK MKM NPA'!AS8+'2026-LPK DKP NPA '!AS8+'2026-LPK CTPS NPA'!AS8+'2026-LPK CDB NPA'!AS8+'2026-OS CTPS NPA'!AS8+'2026-OS CDB NPA'!AS8 -> 0 | AT8: =AR8/$AR$24 -> #DIV/0! | AU8: =AS8/$AS$24 -> #DIV/0! | AV8: =NPA!AV8+NES!AV8+'2026-PKL NPA'!AV8+'2026- Harian NES'!AV8+'2026-Harian NPA'!AV8+'2026-LPK MKS NPA'!AV8+'2026-LPK MKM NPA'!AV8+'2026-LPK DKP NPA '!AV8+'2026-LPK CTPS NPA'!AV8+'2026-LPK CDB NPA'!AV8+'2026-OS CTPS NPA'!AV8+'2026-OS CDB NPA'!AV8 -> 0 | AW8: =NPA!AW8+NES!AW8+'2026-PKL NPA'!AW8+'2026- Harian NES'!AW8+'2026-Harian NPA'!AW8+'2026-LPK MKS NPA'!AW8+'2026-LPK MKM NPA'!AW8+'2026-LPK DKP NPA '!AW8+'2026-LPK CTPS NPA'!AW8+'2026-LPK CDB NPA'!AW8+'2026-OS CTPS NPA'!AW8+'2026-OS CDB NPA'!AW8 -> 0 | AX8: =AV8/$AJ$24 -> #DIV/0! | AY8: =AW8/$AK$24 -> #DIV/0! | AZ8: =E8+I8+M8+Q8+U8+Y8+AC8+AG8+AK8+AO8+AS8+AW8 -> 350174044 | BA8: =AVERAGE(F8,J8,N8,R8,V8,Z8,AD8,AH8,AL8,AP8,AT8,AX8) -> #DIV/0! | BB8: =AVERAGE(G8,K8,O8,S8,W8,AA8,AE8,AI8,AM8,AQ8,AU8,AY8) -> #DIV/0! | BC8: =E8+I8+M8 -> 350174044 | BD8: =Q8+U8+Y8 -> 0 | BE8: =AC8+AG8+AK8 -> 0 | BF8: =AO8+AS8+AW8 -> 0
B9: =B8+1 -> 3 | C9: Marketing | D9: =NPA!D9+NES!D9+'2026-PKL NPA'!D9+'2026- Harian NES'!D9+'2026-Harian NPA'!D9+'2026-LPK MKS NPA'!D9+'2026-LPK MKM NPA'!D9+'2026-LPK DKP NPA '!D9+'2026-LPK CTPS NPA'!D9+'2026-LPK CDB NPA'!D9+'2026-OS CTPS NPA'!D9+'2026-OS CDB NPA'!D9 -> 9 | E9: =NPA!E9+NES!E9+'2026-PKL NPA'!E9+'2026- Harian NES'!E9+'2026-Harian NPA'!E9+'2026-LPK MKS NPA'!E9+'2026-LPK MKM NPA'!E9+'2026-LPK DKP NPA '!E9+'2026-LPK CTPS NPA'!E9+'2026-LPK CDB NPA'!E9+'2026-OS CTPS NPA'!E9+'2026-OS CDB NPA'!E9 -> 146715650 | F9: =D9/$D$24 -> 0.027692308 | G9: =E9/$E$24 -> 0.058740984 | H9: =NPA!H9+NES!H9+'2026-PKL NPA'!H9+'2026- Harian NES'!H9+'2026-Harian NPA'!H9+'2026-LPK MKS NPA'!H9+'2026-LPK MKM NPA'!H9+'2026-LPK DKP NPA '!H9+'2026-LPK CTPS NPA'!H9+'2026-LPK CDB NPA'!H9+'2026-OS CTPS NPA'!H9+'2026-OS CDB NPA'!H9 -> 9 | I9: =NPA!I9+NES!I9+'2026-PKL NPA'!I9+'2026- Harian NES'!I9+'2026-Harian NPA'!I9+'2026-LPK MKS NPA'!I9+'2026-LPK MKM NPA'!I9+'2026-LPK DKP NPA '!I9+'2026-LPK CTPS NPA'!I9+'2026-LPK CDB NPA'!I9+'2026-OS CTPS NPA'!I9+'2026-OS CDB NPA'!I9 -> 132343337 | J9: =H9/$H$24 -> 0.028938907 | K9: =I9/$I$24 -> 0.056846847 | L9: =NPA!L9+NES!L9+'2026-PKL NPA'!L9+'2026- Harian NES'!L9+'2026-Harian NPA'!L9+'2026-LPK MKS NPA'!L9+'2026-LPK MKM NPA'!L9+'2026-LPK DKP NPA '!L9+'2026-LPK CTPS NPA'!L9+'2026-LPK CDB NPA'!L9+'2026-OS CTPS NPA'!L9+'2026-OS CDB NPA'!L9 -> 9 | M9: =NPA!M9+NES!M9+'2026-PKL NPA'!M9+'2026- Harian NES'!M9+'2026-Harian NPA'!M9+'2026-LPK MKS NPA'!M9+'2026-LPK MKM NPA'!M9+'2026-LPK DKP NPA '!M9+'2026-LPK CTPS NPA'!M9+'2026-LPK CDB NPA'!M9+'2026-OS CTPS NPA'!M9+'2026-OS CDB NPA'!M9 -> 130048727 | N9: =L9/$L$24 -> 0.028938907 | O9: =M9/$M$24 -> 0.059965402 | P9: =NPA!P9+NES!P9+'2026-PKL NPA'!P9+'2026- Harian NES'!P9+'2026-Harian NPA'!P9+'2026-LPK MKS NPA'!P9+'2026-LPK MKM NPA'!P9+'2026-LPK DKP NPA '!P9+'2026-LPK CTPS NPA'!P9+'2026-LPK CDB NPA'!P9+'2026-OS CTPS NPA'!P9+'2026-OS CDB NPA'!P9 -> 0 | Q9: =NPA!Q9+NES!Q9+'2026-PKL NPA'!Q9+'2026- Harian NES'!Q9+'2026-Harian NPA'!Q9+'2026-LPK MKS NPA'!Q9+'2026-LPK MKM NPA'!Q9+'2026-LPK DKP NPA '!Q9+'2026-LPK CTPS NPA'!Q9+'2026-LPK CDB NPA'!Q9+'2026-OS CTPS NPA'!Q9+'2026-OS CDB NPA'!Q9 -> 0 | R9: =P9/$P$24 -> #DIV/0! | S9: =Q9/$Q$24 -> #DIV/0! | T9: =NPA!T9+NES!T9+'2026-PKL NPA'!T9+'2026- Harian NES'!T9+'2026-Harian NPA'!T9+'2026-LPK MKS NPA'!T9+'2026-LPK MKM NPA'!T9+'2026-LPK DKP NPA '!T9+'2026-LPK CTPS NPA'!T9+'2026-LPK CDB NPA'!T9+'2026-OS CTPS NPA'!T9+'2026-OS CDB NPA'!T9 -> 0 | U9: =NPA!U9+NES!U9+'2026-PKL NPA'!U9+'2026- Harian NES'!U9+'2026-Harian NPA'!U9+'2026-LPK MKS NPA'!U9+'2026-LPK MKM NPA'!U9+'2026-LPK DKP NPA '!U9+'2026-LPK CTPS NPA'!U9+'2026-LPK CDB NPA'!U9+'2026-OS CTPS NPA'!U9+'2026-OS CDB NPA'!U9 -> 0 | V9: =T9/$T$24 -> #DIV/0! | W9: =U9/$U$24 -> #DIV/0! | X9: =NPA!X9+NES!X9+'2026-PKL NPA'!X9+'2026- Harian NES'!X9+'2026-Harian NPA'!X9+'2026-LPK MKS NPA'!X9+'2026-LPK MKM NPA'!X9+'2026-LPK DKP NPA '!X9+'2026-LPK CTPS NPA'!X9+'2026-LPK CDB NPA'!X9+'2026-OS CTPS NPA'!X9+'2026-OS CDB NPA'!X9 -> 0 | Y9: =NPA!Y9+NES!Y9+'2026-PKL NPA'!Y9+'2026- Harian NES'!Y9+'2026-Harian NPA'!Y9+'2026-LPK MKS NPA'!Y9+'2026-LPK MKM NPA'!Y9+'2026-LPK DKP NPA '!Y9+'2026-LPK CTPS NPA'!Y9+'2026-LPK CDB NPA'!Y9+'2026-OS CTPS NPA'!Y9+'2026-OS CDB NPA'!Y9 -> 0 | Z9: =X9/$X$24 -> #DIV/0! | AA9: =Y9/$Y$24 -> #DIV/0! | AB9: =NPA!AB9+NES!AB9+'2026-PKL NPA'!AB9+'2026- Harian NES'!AB9+'2026-Harian NPA'!AB9+'2026-LPK MKS NPA'!AB9+'2026-LPK MKM NPA'!AB9+'2026-LPK DKP NPA '!AB9+'2026-LPK CTPS NPA'!AB9+'2026-LPK CDB NPA'!AB9+'2026-OS CTPS NPA'!AB9+'2026-OS CDB NPA'!AB9 -> 0 | AC9: =NPA!AC9+NES!AC9+'2026-PKL NPA'!AC9+'2026- Harian NES'!AC9+'2026-Harian NPA'!AC9+'2026-LPK MKS NPA'!AC9+'2026-LPK MKM NPA'!AC9+'2026-LPK DKP NPA '!AC9+'2026-LPK CTPS NPA'!AC9+'2026-LPK CDB NPA'!AC9+'2026-OS CTPS NPA'!AC9+'2026-OS CDB NPA'!AC9 -> 0 | AD9: =AB9/$AB$24 -> #DIV/0! | AE9: =AC9/$AC$24 -> #DIV/0! | AF9: =NPA!AF9+NES!AF9+'2026-PKL NPA'!AF9+'2026- Harian NES'!AF9+'2026-Harian NPA'!AF9+'2026-LPK MKS NPA'!AF9+'2026-LPK MKM NPA'!AF9+'2026-LPK DKP NPA '!AF9+'2026-LPK CTPS NPA'!AF9+'2026-LPK CDB NPA'!AF9+'2026-OS CTPS NPA'!AF9+'2026-OS CDB NPA'!AF9 -> 0 | AG9: =NPA!AG9+NES!AG9+'2026-PKL NPA'!AG9+'2026- Harian NES'!AG9+'2026-Harian NPA'!AG9+'2026-LPK MKS NPA'!AG9+'2026-LPK MKM NPA'!AG9+'2026-LPK DKP NPA '!AG9+'2026-LPK CTPS NPA'!AG9+'2026-LPK CDB NPA'!AG9+'2026-OS CTPS NPA'!AG9+'2026-OS CDB NPA'!AG9 -> 0 | AH9: =AF9/$AF$24 -> #DIV/0! | AI9: =AG9/$AG$24 -> #DIV/0! | AJ9: =NPA!AJ9+NES!AJ9+'2026-PKL NPA'!AJ9+'2026- Harian NES'!AJ9+'2026-Harian NPA'!AJ9+'2026-LPK MKS NPA'!AJ9+'2026-LPK MKM NPA'!AJ9+'2026-LPK DKP NPA '!AJ9+'2026-LPK CTPS NPA'!AJ9+'2026-LPK CDB NPA'!AJ9+'2026-OS CTPS NPA'!AJ9+'2026-OS CDB NPA'!AJ9 -> 0 | AK9: =NPA!AK9+NES!AK9+'2026-PKL NPA'!AK9+'2026- Harian NES'!AK9+'2026-Harian NPA'!AK9+'2026-LPK MKS NPA'!AK9+'2026-LPK MKM NPA'!AK9+'2026-LPK DKP NPA '!AK9+'2026-LPK CTPS NPA'!AK9+'2026-LPK CDB NPA'!AK9+'2026-OS CTPS NPA'!AK9+'2026-OS CDB NPA'!AK9 -> 0 | AL9: =AJ9/$AJ$24 -> #DIV/0! | AM9: =AK9/$AK$24 -> #DIV/0! | AN9: =NPA!AN9+NES!AN9+'2026-PKL NPA'!AN9+'2026- Harian NES'!AN9+'2026-Harian NPA'!AN9+'2026-LPK MKS NPA'!AN9+'2026-LPK MKM NPA'!AN9+'2026-LPK DKP NPA '!AN9+'2026-LPK CTPS NPA'!AN9+'2026-LPK CDB NPA'!AN9+'2026-OS CTPS NPA'!AN9+'2026-OS CDB NPA'!AN9 -> 0 | AO9: =NPA!AO9+NES!AO9+'2026-PKL NPA'!AO9+'2026- Harian NES'!AO9+'2026-Harian NPA'!AO9+'2026-LPK MKS NPA'!AO9+'2026-LPK MKM NPA'!AO9+'2026-LPK DKP NPA '!AO9+'2026-LPK CTPS NPA'!AO9+'2026-LPK CDB NPA'!AO9+'2026-OS CTPS NPA'!AO9+'2026-OS CDB NPA'!AO9 -> 0 | AP9: =AN9/$AN$24 -> #DIV/0! | AQ9: =AO9/$AO$24 -> #DIV/0! | AR9: =NPA!AR9+NES!AR9+'2026-PKL NPA'!AR9+'2026- Harian NES'!AR9+'2026-Harian NPA'!AR9+'2026-LPK MKS NPA'!AR9+'2026-LPK MKM NPA'!AR9+'2026-LPK DKP NPA '!AR9+'2026-LPK CTPS NPA'!AR9+'2026-LPK CDB NPA'!AR9+'2026-OS CTPS NPA'!AR9+'2026-OS CDB NPA'!AR9 -> 0 | AS9: =NPA!AS9+NES!AS9+'2026-PKL NPA'!AS9+'2026- Harian NES'!AS9+'2026-Harian NPA'!AS9+'2026-LPK MKS NPA'!AS9+'2026-LPK MKM NPA'!AS9+'2026-LPK DKP NPA '!AS9+'2026-LPK CTPS NPA'!AS9+'2026-LPK CDB NPA'!AS9+'2026-OS CTPS NPA'!AS9+'2026-OS CDB NPA'!AS9 -> 0 | AT9: =AR9/$AR$24 -> #DIV/0! | AU9: =AS9/$AS$24 -> #DIV/0! | AV9: =NPA!AV9+NES!AV9+'2026-PKL NPA'!AV9+'2026- Harian NES'!AV9+'2026-Harian NPA'!AV9+'2026-LPK MKS NPA'!AV9+'2026-LPK MKM NPA'!AV9+'2026-LPK DKP NPA '!AV9+'2026-LPK CTPS NPA'!AV9+'2026-LPK CDB NPA'!AV9+'2026-OS CTPS NPA'!AV9+'2026-OS CDB NPA'!AV9 -> 0 | AW9: =NPA!AW9+NES!AW9+'2026-PKL NPA'!AW9+'2026- Harian NES'!AW9+'2026-Harian NPA'!AW9+'2026-LPK MKS NPA'!AW9+'2026-LPK MKM NPA'!AW9+'2026-LPK DKP NPA '!AW9+'2026-LPK CTPS NPA'!AW9+'2026-LPK CDB NPA'!AW9+'2026-OS CTPS NPA'!AW9+'2026-OS CDB NPA'!AW9 -> 0 | AX9: =AV9/$AJ$24 -> #DIV/0! | AY9: =AW9/$AK$24 -> #DIV/0! | AZ9: =E9+I9+M9+Q9+U9+Y9+AC9+AG9+AK9+AO9+AS9+AW9 -> 409107714 | BA9: =AVERAGE(F9,J9,N9,R9,V9,Z9,AD9,AH9,AL9,AP9,AT9,AX9) -> #DIV/0! | BB9: =AVERAGE(G9,K9,O9,S9,W9,AA9,AE9,AI9,AM9,AQ9,AU9,AY9) -> #DIV/0! | BC9: =E9+I9+M9 -> 409107714 | BD9: =Q9+U9+Y9 -> 0 | BE9: =AC9+AG9+AK9 -> 0 | BF9: =AO9+AS9+AW9 -> 0
B10: =B9+1 -> 4 | C10: Elektrikal | D10: =NPA!D10+NES!D10+'2026-PKL NPA'!D10+'2026- Harian NES'!D10+'2026-Harian NPA'!D10+'2026-LPK MKS NPA'!D10+'2026-LPK MKM NPA'!D10+'2026-LPK DKP NPA '!D10+'2026-LPK CTPS NPA'!D10+'2026-LPK CDB NPA'!D10+'2026-OS CTPS NPA'!D10+'2026-OS CDB NPA'!D10 -> 33 | E10: =NPA!E10+NES!E10+'2026-PKL NPA'!E10+'2026- Harian NES'!E10+'2026-Harian NPA'!E10+'2026-LPK MKS NPA'!E10+'2026-LPK MKM NPA'!E10+'2026-LPK DKP NPA '!E10+'2026-LPK CTPS NPA'!E10+'2026-LPK CDB NPA'!E10+'2026-OS CTPS NPA'!E10+'2026-OS CDB NPA'!E10 -> 268678767 | F10: =D10/$D$24 -> 0.10153846 | G10: =E10/$E$24 -> 0.10757172 | H10: =NPA!H10+NES!H10+'2026-PKL NPA'!H10+'2026- Harian NES'!H10+'2026-Harian NPA'!H10+'2026-LPK MKS NPA'!H10+'2026-LPK MKM NPA'!H10+'2026-LPK DKP NPA '!H10+'2026-LPK CTPS NPA'!H10+'2026-LPK CDB NPA'!H10+'2026-OS CTPS NPA'!H10+'2026-OS CDB NPA'!H10 -> 31 | I10: =NPA!I10+NES!I10+'2026-PKL NPA'!I10+'2026- Harian NES'!I10+'2026-Harian NPA'!I10+'2026-LPK MKS NPA'!I10+'2026-LPK MKM NPA'!I10+'2026-LPK DKP NPA '!I10+'2026-LPK CTPS NPA'!I10+'2026-LPK CDB NPA'!I10+'2026-OS CTPS NPA'!I10+'2026-OS CDB NPA'!I10 -> 233978970 | J10: =H10/$H$24 -> 0.099678457 | K10: =I10/$I$24 -> 0.10050349 | L10: =NPA!L10+NES!L10+'2026-PKL NPA'!L10+'2026- Harian NES'!L10+'2026-Harian NPA'!L10+'2026-LPK MKS NPA'!L10+'2026-LPK MKM NPA'!L10+'2026-LPK DKP NPA '!L10+'2026-LPK CTPS NPA'!L10+'2026-LPK CDB NPA'!L10+'2026-OS CTPS NPA'!L10+'2026-OS CDB NPA'!L10 -> 31 | M10: =NPA!M10+NES!M10+'2026-PKL NPA'!M10+'2026- Harian NES'!M10+'2026-Harian NPA'!M10+'2026-LPK MKS NPA'!M10+'2026-LPK MKM NPA'!M10+'2026-LPK DKP NPA '!M10+'2026-LPK CTPS NPA'!M10+'2026-LPK CDB NPA'!M10+'2026-OS CTPS NPA'!M10+'2026-OS CDB NPA'!M10 -> 228349028 | N10: =L10/$L$24 -> 0.099678457 | O10: =M10/$M$24 -> 0.10529162 | P10: =NPA!P10+NES!P10+'2026-PKL NPA'!P10+'2026- Harian NES'!P10+'2026-Harian NPA'!P10+'2026-LPK MKS NPA'!P10+'2026-LPK MKM NPA'!P10+'2026-LPK DKP NPA '!P10+'2026-LPK CTPS NPA'!P10+'2026-LPK CDB NPA'!P10+'2026-OS CTPS NPA'!P10+'2026-OS CDB NPA'!P10 -> 0 | Q10: =NPA!Q10+NES!Q10+'2026-PKL NPA'!Q10+'2026- Harian NES'!Q10+'2026-Harian NPA'!Q10+'2026-LPK MKS NPA'!Q10+'2026-LPK MKM NPA'!Q10+'2026-LPK DKP NPA '!Q10+'2026-LPK CTPS NPA'!Q10+'2026-LPK CDB NPA'!Q10+'2026-OS CTPS NPA'!Q10+'2026-OS CDB NPA'!Q10 -> 0 | R10: =P10/$P$24 -> #DIV/0! | S10: =Q10/$Q$24 -> #DIV/0! | T10: =NPA!T10+NES!T10+'2026-PKL NPA'!T10+'2026- Harian NES'!T10+'2026-Harian NPA'!T10+'2026-LPK MKS NPA'!T10+'2026-LPK MKM NPA'!T10+'2026-LPK DKP NPA '!T10+'2026-LPK CTPS NPA'!T10+'2026-LPK CDB NPA'!T10+'2026-OS CTPS NPA'!T10+'2026-OS CDB NPA'!T10 -> 0 | U10: =NPA!U10+NES!U10+'2026-PKL NPA'!U10+'2026- Harian NES'!U10+'2026-Harian NPA'!U10+'2026-LPK MKS NPA'!U10+'2026-LPK MKM NPA'!U10+'2026-LPK DKP NPA '!U10+'2026-LPK CTPS NPA'!U10+'2026-LPK CDB NPA'!U10+'2026-OS CTPS NPA'!U10+'2026-OS CDB NPA'!U10 -> 0 | V10: =T10/$T$24 -> #DIV/0! | W10: =U10/$U$24 -> #DIV/0! | X10: =NPA!X10+NES!X10+'2026-PKL NPA'!X10+'2026- Harian NES'!X10+'2026-Harian NPA'!X10+'2026-LPK MKS NPA'!X10+'2026-LPK MKM NPA'!X10+'2026-LPK DKP NPA '!X10+'2026-LPK CTPS NPA'!X10+'2026-LPK CDB NPA'!X10+'2026-OS CTPS NPA'!X10+'2026-OS CDB NPA'!X10 -> 0 | Y10: =NPA!Y10+NES!Y10+'2026-PKL NPA'!Y10+'2026- Harian NES'!Y10+'2026-Harian NPA'!Y10+'2026-LPK MKS NPA'!Y10+'2026-LPK MKM NPA'!Y10+'2026-LPK DKP NPA '!Y10+'2026-LPK CTPS NPA'!Y10+'2026-LPK CDB NPA'!Y10+'2026-OS CTPS NPA'!Y10+'2026-OS CDB NPA'!Y10 -> 0 | Z10: =X10/$X$24 -> #DIV/0! | AA10: =Y10/$Y$24 -> #DIV/0! | AB10: =NPA!AB10+NES!AB10+'2026-PKL NPA'!AB10+'2026- Harian NES'!AB10+'2026-Harian NPA'!AB10+'2026-LPK MKS NPA'!AB10+'2026-LPK MKM NPA'!AB10+'2026-LPK DKP NPA '!AB10+'2026-LPK CTPS NPA'!AB10+'2026-LPK CDB NPA'!AB10+'2026-OS CTPS NPA'!AB10+'2026-OS CDB NPA'!AB10 -> 0 | AC10: =NPA!AC10+NES!AC10+'2026-PKL NPA'!AC10+'2026- Harian NES'!AC10+'2026-Harian NPA'!AC10+'2026-LPK MKS NPA'!AC10+'2026-LPK MKM NPA'!AC10+'2026-LPK DKP NPA '!AC10+'2026-LPK CTPS NPA'!AC10+'2026-LPK CDB NPA'!AC10+'2026-OS CTPS NPA'!AC10+'2026-OS CDB NPA'!AC10 -> 0 | AD10: =AB10/$AB$24 -> #DIV/0! | AE10: =AC10/$AC$24 -> #DIV/0! | AF10: =NPA!AF10+NES!AF10+'2026-PKL NPA'!AF10+'2026- Harian NES'!AF10+'2026-Harian NPA'!AF10+'2026-LPK MKS NPA'!AF10+'2026-LPK MKM NPA'!AF10+'2026-LPK DKP NPA '!AF10+'2026-LPK CTPS NPA'!AF10+'2026-LPK CDB NPA'!AF10+'2026-OS CTPS NPA'!AF10+'2026-OS CDB NPA'!AF10 -> 0 | AG10: =NPA!AG10+NES!AG10+'2026-PKL NPA'!AG10+'2026- Harian NES'!AG10+'2026-Harian NPA'!AG10+'2026-LPK MKS NPA'!AG10+'2026-LPK MKM NPA'!AG10+'2026-LPK DKP NPA '!AG10+'2026-LPK CTPS NPA'!AG10+'2026-LPK CDB NPA'!AG10+'2026-OS CTPS NPA'!AG10+'2026-OS CDB NPA'!AG10 -> 0 | AH10: =AF10/$AF$24 -> #DIV/0! | AI10: =AG10/$AG$24 -> #DIV/0! | AJ10: =NPA!AJ10+NES!AJ10+'2026-PKL NPA'!AJ10+'2026- Harian NES'!AJ10+'2026-Harian NPA'!AJ10+'2026-LPK MKS NPA'!AJ10+'2026-LPK MKM NPA'!AJ10+'2026-LPK DKP NPA '!AJ10+'2026-LPK CTPS NPA'!AJ10+'2026-LPK CDB NPA'!AJ10+'2026-OS CTPS NPA'!AJ10+'2026-OS CDB NPA'!AJ10 -> 0 | AK10: =NPA!AK10+NES!AK10+'2026-PKL NPA'!AK10+'2026- Harian NES'!AK10+'2026-Harian NPA'!AK10+'2026-LPK MKS NPA'!AK10+'2026-LPK MKM NPA'!AK10+'2026-LPK DKP NPA '!AK10+'2026-LPK CTPS NPA'!AK10+'2026-LPK CDB NPA'!AK10+'2026-OS CTPS NPA'!AK10+'2026-OS CDB NPA'!AK10 -> 0 | AL10: =AJ10/$AJ$24 -> #DIV/0! | AM10: =AK10/$AK$24 -> #DIV/0! | AN10: =NPA!AN10+NES!AN10+'2026-PKL NPA'!AN10+'2026- Harian NES'!AN10+'2026-Harian NPA'!AN10+'2026-LPK MKS NPA'!AN10+'2026-LPK MKM NPA'!AN10+'2026-LPK DKP NPA '!AN10+'2026-LPK CTPS NPA'!AN10+'2026-LPK CDB NPA'!AN10+'2026-OS CTPS NPA'!AN10+'2026-OS CDB NPA'!AN10 -> 0 | AO10: =NPA!AO10+NES!AO10+'2026-PKL NPA'!AO10+'2026- Harian NES'!AO10+'2026-Harian NPA'!AO10+'2026-LPK MKS NPA'!AO10+'2026-LPK MKM NPA'!AO10+'2026-LPK DKP NPA '!AO10+'2026-LPK CTPS NPA'!AO10+'2026-LPK CDB NPA'!AO10+'2026-OS CTPS NPA'!AO10+'2026-OS CDB NPA'!AO10 -> 0 | AP10: =AN10/$AN$24 -> #DIV/0! | AQ10: =AO10/$AO$24 -> #DIV/0! | AR10: =NPA!AR10+NES!AR10+'2026-PKL NPA'!AR10+'2026- Harian NES'!AR10+'2026-Harian NPA'!AR10+'2026-LPK MKS NPA'!AR10+'2026-LPK MKM NPA'!AR10+'2026-LPK DKP NPA '!AR10+'2026-LPK CTPS NPA'!AR10+'2026-LPK CDB NPA'!AR10+'2026-OS CTPS NPA'!AR10+'2026-OS CDB NPA'!AR10 -> 0 | AS10: =NPA!AS10+NES!AS10+'2026-PKL NPA'!AS10+'2026- Harian NES'!AS10+'2026-Harian NPA'!AS10+'2026-LPK MKS NPA'!AS10+'2026-LPK MKM NPA'!AS10+'2026-LPK DKP NPA '!AS10+'2026-LPK CTPS NPA'!AS10+'2026-LPK CDB NPA'!AS10+'2026-OS CTPS NPA'!AS10+'2026-OS CDB NPA'!AS10 -> 0 | AT10: =AR10/$AR$24 -> #DIV/0! | AU10: =AS10/$AS$24 -> #DIV/0! | AV10: =NPA!AV10+NES!AV10+'2026-PKL NPA'!AV10+'2026- Harian NES'!AV10+'2026-Harian NPA'!AV10+'2026-LPK MKS NPA'!AV10+'2026-LPK MKM NPA'!AV10+'2026-LPK DKP NPA '!AV10+'2026-LPK CTPS NPA'!AV10+'2026-LPK CDB NPA'!AV10+'2026-OS CTPS NPA'!AV10+'2026-OS CDB NPA'!AV10 -> 0 | AW10: =NPA!AW10+NES!AW10+'2026-PKL NPA'!AW10+'2026- Harian NES'!AW10+'2026-Harian NPA'!AW10+'2026-LPK MKS NPA'!AW10+'2026-LPK MKM NPA'!AW10+'2026-LPK DKP NPA '!AW10+'2026-LPK CTPS NPA'!AW10+'2026-LPK CDB NPA'!AW10+'2026-OS CTPS NPA'!AW10+'2026-OS CDB NPA'!AW10 -> 0 | AX10: =AV10/$AJ$24 -> #DIV/0! | AY10: =AW10/$AK$24 -> #DIV/0! | AZ10: =E10+I10+M10+Q10+U10+Y10+AC10+AG10+AK10+AO10+AS10+AW10 -> 731006765 | BA10: =AVERAGE(F10,J10,N10,R10,V10,Z10,AD10,AH10,AL10,AP10,AT10,AX10) -> #DIV/0! | BB10: =AVERAGE(G10,K10,O10,S10,W10,AA10,AE10,AI10,AM10,AQ10,AU10,AY10) -> #DIV/0! | BC10: =E10+I10+M10 -> 731006765 | BD10: =Q10+U10+Y10 -> 0 | BE10: =AC10+AG10+AK10 -> 0 | BF10: =AO10+AS10+AW10 -> 0
B11: =B10+1 -> 5 | C11: Purchasing & EIM | D11: =NPA!D11+NES!D11+'2026-PKL NPA'!D11+'2026- Harian NES'!D11+'2026-Harian NPA'!D11+'2026-LPK MKS NPA'!D11+'2026-LPK MKM NPA'!D11+'2026-LPK DKP NPA '!D11+'2026-LPK CTPS NPA'!D11+'2026-LPK CDB NPA'!D11+'2026-OS CTPS NPA'!D11+'2026-OS CDB NPA'!D11 -> 5 | E11: =NPA!E11+NES!E11+'2026-PKL NPA'!E11+'2026- Harian NES'!E11+'2026-Harian NPA'!E11+'2026-LPK MKS NPA'!E11+'2026-LPK MKM NPA'!E11+'2026-LPK DKP NPA '!E11+'2026-LPK CTPS NPA'!E11+'2026-LPK CDB NPA'!E11+'2026-OS CTPS NPA'!E11+'2026-OS CDB NPA'!E11 -> 56116099 | F11: =D11/$D$24 -> 0.015384615 | G11: =E11/$E$24 -> 0.02246737 | H11: =NPA!H11+NES!H11+'2026-PKL NPA'!H11+'2026- Harian NES'!H11+'2026-Harian NPA'!H11+'2026-LPK MKS NPA'!H11+'2026-LPK MKM NPA'!H11+'2026-LPK DKP NPA '!H11+'2026-LPK CTPS NPA'!H11+'2026-LPK CDB NPA'!H11+'2026-OS CTPS NPA'!H11+'2026-OS CDB NPA'!H11 -> 5 | I11: =NPA!I11+NES!I11+'2026-PKL NPA'!I11+'2026- Harian NES'!I11+'2026-Harian NPA'!I11+'2026-LPK MKS NPA'!I11+'2026-LPK MKM NPA'!I11+'2026-LPK DKP NPA '!I11+'2026-LPK CTPS NPA'!I11+'2026-LPK CDB NPA'!I11+'2026-OS CTPS NPA'!I11+'2026-OS CDB NPA'!I11 -> 54749422 | J11: =H11/$H$24 -> 0.01607717 | K11: =I11/$I$24 -> 0.023517104 | L11: =NPA!L11+NES!L11+'2026-PKL NPA'!L11+'2026- Harian NES'!L11+'2026-Harian NPA'!L11+'2026-LPK MKS NPA'!L11+'2026-LPK MKM NPA'!L11+'2026-LPK DKP NPA '!L11+'2026-LPK CTPS NPA'!L11+'2026-LPK CDB NPA'!L11+'2026-OS CTPS NPA'!L11+'2026-OS CDB NPA'!L11 -> 5 | M11: =NPA!M11+NES!M11+'2026-PKL NPA'!M11+'2026- Harian NES'!M11+'2026-Harian NPA'!M11+'2026-LPK MKS NPA'!M11+'2026-LPK MKM NPA'!M11+'2026-LPK DKP NPA '!M11+'2026-LPK CTPS NPA'!M11+'2026-LPK CDB NPA'!M11+'2026-OS CTPS NPA'!M11+'2026-OS CDB NPA'!M11 -> 52851029 | N11: =L11/$L$24 -> 0.01607717 | O11: =M11/$M$24 -> 0.024369583 | P11: =NPA!P11+NES!P11+'2026-PKL NPA'!P11+'2026- Harian NES'!P11+'2026-Harian NPA'!P11+'2026-LPK MKS NPA'!P11+'2026-LPK MKM NPA'!P11+'2026-LPK DKP NPA '!P11+'2026-LPK CTPS NPA'!P11+'2026-LPK CDB NPA'!P11+'2026-OS CTPS NPA'!P11+'2026-OS CDB NPA'!P11 -> 0 | Q11: =NPA!Q11+NES!Q11+'2026-PKL NPA'!Q11+'2026- Harian NES'!Q11+'2026-Harian NPA'!Q11+'2026-LPK MKS NPA'!Q11+'2026-LPK MKM NPA'!Q11+'2026-LPK DKP NPA '!Q11+'2026-LPK CTPS NPA'!Q11+'2026-LPK CDB NPA'!Q11+'2026-OS CTPS NPA'!Q11+'2026-OS CDB NPA'!Q11 -> 0 | R11: =P11/$P$24 -> #DIV/0! | S11: =Q11/$Q$24 -> #DIV/0! | T11: =NPA!T11+NES!T11+'2026-PKL NPA'!T11+'2026- Harian NES'!T11+'2026-Harian NPA'!T11+'2026-LPK MKS NPA'!T11+'2026-LPK MKM NPA'!T11+'2026-LPK DKP NPA '!T11+'2026-LPK CTPS NPA'!T11+'2026-LPK CDB NPA'!T11+'2026-OS CTPS NPA'!T11+'2026-OS CDB NPA'!T11 -> 0 | U11: =NPA!U11+NES!U11+'2026-PKL NPA'!U11+'2026- Harian NES'!U11+'2026-Harian NPA'!U11+'2026-LPK MKS NPA'!U11+'2026-LPK MKM NPA'!U11+'2026-LPK DKP NPA '!U11+'2026-LPK CTPS NPA'!U11+'2026-LPK CDB NPA'!U11+'2026-OS CTPS NPA'!U11+'2026-OS CDB NPA'!U11 -> 0 | V11: =T11/$T$24 -> #DIV/0! | W11: =U11/$U$24 -> #DIV/0! | X11: =NPA!X11+NES!X11+'2026-PKL NPA'!X11+'2026- Harian NES'!X11+'2026-Harian NPA'!X11+'2026-LPK MKS NPA'!X11+'2026-LPK MKM NPA'!X11+'2026-LPK DKP NPA '!X11+'2026-LPK CTPS NPA'!X11+'2026-LPK CDB NPA'!X11+'2026-OS CTPS NPA'!X11+'2026-OS CDB NPA'!X11 -> 0 | Y11: =NPA!Y11+NES!Y11+'2026-PKL NPA'!Y11+'2026- Harian NES'!Y11+'2026-Harian NPA'!Y11+'2026-LPK MKS NPA'!Y11+'2026-LPK MKM NPA'!Y11+'2026-LPK DKP NPA '!Y11+'2026-LPK CTPS NPA'!Y11+'2026-LPK CDB NPA'!Y11+'2026-OS CTPS NPA'!Y11+'2026-OS CDB NPA'!Y11 -> 0 | Z11: =X11/$X$24 -> #DIV/0! | AA11: =Y11/$Y$24 -> #DIV/0! | AB11: =NPA!AB11+NES!AB11+'2026-PKL NPA'!AB11+'2026- Harian NES'!AB11+'2026-Harian NPA'!AB11+'2026-LPK MKS NPA'!AB11+'2026-LPK MKM NPA'!AB11+'2026-LPK DKP NPA '!AB11+'2026-LPK CTPS NPA'!AB11+'2026-LPK CDB NPA'!AB11+'2026-OS CTPS NPA'!AB11+'2026-OS CDB NPA'!AB11 -> 0 | AC11: =NPA!AC11+NES!AC11+'2026-PKL NPA'!AC11+'2026- Harian NES'!AC11+'2026-Harian NPA'!AC11+'2026-LPK MKS NPA'!AC11+'2026-LPK MKM NPA'!AC11+'2026-LPK DKP NPA '!AC11+'2026-LPK CTPS NPA'!AC11+'2026-LPK CDB NPA'!AC11+'2026-OS CTPS NPA'!AC11+'2026-OS CDB NPA'!AC11 -> 0 | AD11: =AB11/$AB$24 -> #DIV/0! | AE11: =AC11/$AC$24 -> #DIV/0! | AF11: =NPA!AF11+NES!AF11+'2026-PKL NPA'!AF11+'2026- Harian NES'!AF11+'2026-Harian NPA'!AF11+'2026-LPK MKS NPA'!AF11+'2026-LPK MKM NPA'!AF11+'2026-LPK DKP NPA '!AF11+'2026-LPK CTPS NPA'!AF11+'2026-LPK CDB NPA'!AF11+'2026-OS CTPS NPA'!AF11+'2026-OS CDB NPA'!AF11 -> 0 | AG11: =NPA!AG11+NES!AG11+'2026-PKL NPA'!AG11+'2026- Harian NES'!AG11+'2026-Harian NPA'!AG11+'2026-LPK MKS NPA'!AG11+'2026-LPK MKM NPA'!AG11+'2026-LPK DKP NPA '!AG11+'2026-LPK CTPS NPA'!AG11+'2026-LPK CDB NPA'!AG11+'2026-OS CTPS NPA'!AG11+'2026-OS CDB NPA'!AG11 -> 0 | AH11: =AF11/$AF$24 -> #DIV/0! | AI11: =AG11/$AG$24 -> #DIV/0! | AJ11: =NPA!AJ11+NES!AJ11+'2026-PKL NPA'!AJ11+'2026- Harian NES'!AJ11+'2026-Harian NPA'!AJ11+'2026-LPK MKS NPA'!AJ11+'2026-LPK MKM NPA'!AJ11+'2026-LPK DKP NPA '!AJ11+'2026-LPK CTPS NPA'!AJ11+'2026-LPK CDB NPA'!AJ11+'2026-OS CTPS NPA'!AJ11+'2026-OS CDB NPA'!AJ11 -> 0 | AK11: =NPA!AK11+NES!AK11+'2026-PKL NPA'!AK11+'2026- Harian NES'!AK11+'2026-Harian NPA'!AK11+'2026-LPK MKS NPA'!AK11+'2026-LPK MKM NPA'!AK11+'2026-LPK DKP NPA '!AK11+'2026-LPK CTPS NPA'!AK11+'2026-LPK CDB NPA'!AK11+'2026-OS CTPS NPA'!AK11+'2026-OS CDB NPA'!AK11 -> 0 | AL11: =AJ11/$AJ$24 -> #DIV/0! | AM11: =AK11/$AK$24 -> #DIV/0! | AN11: =NPA!AN11+NES!AN11+'2026-PKL NPA'!AN11+'2026- Harian NES'!AN11+'2026-Harian NPA'!AN11+'2026-LPK MKS NPA'!AN11+'2026-LPK MKM NPA'!AN11+'2026-LPK DKP NPA '!AN11+'2026-LPK CTPS NPA'!AN11+'2026-LPK CDB NPA'!AN11+'2026-OS CTPS NPA'!AN11+'2026-OS CDB NPA'!AN11 -> 0 | AO11: =NPA!AO11+NES!AO11+'2026-PKL NPA'!AO11+'2026- Harian NES'!AO11+'2026-Harian NPA'!AO11+'2026-LPK MKS NPA'!AO11+'2026-LPK MKM NPA'!AO11+'2026-LPK DKP NPA '!AO11+'2026-LPK CTPS NPA'!AO11+'2026-LPK CDB NPA'!AO11+'2026-OS CTPS NPA'!AO11+'2026-OS CDB NPA'!AO11 -> 0 | AP11: =AN11/$AN$24 -> #DIV/0! | AQ11: =AO11/$AO$24 -> #DIV/0! | AR11: =NPA!AR11+NES!AR11+'2026-PKL NPA'!AR11+'2026- Harian NES'!AR11+'2026-Harian NPA'!AR11+'2026-LPK MKS NPA'!AR11+'2026-LPK MKM NPA'!AR11+'2026-LPK DKP NPA '!AR11+'2026-LPK CTPS NPA'!AR11+'2026-LPK CDB NPA'!AR11+'2026-OS CTPS NPA'!AR11+'2026-OS CDB NPA'!AR11 -> 0 | AS11: =NPA!AS11+NES!AS11+'2026-PKL NPA'!AS11+'2026- Harian NES'!AS11+'2026-Harian NPA'!AS11+'2026-LPK MKS NPA'!AS11+'2026-LPK MKM NPA'!AS11+'2026-LPK DKP NPA '!AS11+'2026-LPK CTPS NPA'!AS11+'2026-LPK CDB NPA'!AS11+'2026-OS CTPS NPA'!AS11+'2026-OS CDB NPA'!AS11 -> 0 | AT11: =AR11/$AR$24 -> #DIV/0! | AU11: =AS11/$AS$24 -> #DIV/0! | AV11: =NPA!AV11+NES!AV11+'2026-PKL NPA'!AV11+'2026- Harian NES'!AV11+'2026-Harian NPA'!AV11+'2026-LPK MKS NPA'!AV11+'2026-LPK MKM NPA'!AV11+'2026-LPK DKP NPA '!AV11+'2026-LPK CTPS NPA'!AV11+'2026-LPK CDB NPA'!AV11+'2026-OS CTPS NPA'!AV11+'2026-OS CDB NPA'!AV11 -> 0 | AW11: =NPA!AW11+NES!AW11+'2026-PKL NPA'!AW11+'2026- Harian NES'!AW11+'2026-Harian NPA'!AW11+'2026-LPK MKS NPA'!AW11+'2026-LPK MKM NPA'!AW11+'2026-LPK DKP NPA '!AW11+'2026-LPK CTPS NPA'!AW11+'2026-LPK CDB NPA'!AW11+'2026-OS CTPS NPA'!AW11+'2026-OS CDB NPA'!AW11 -> 0 | AX11: =AV11/$AJ$24 -> #DIV/0! | AY11: =AW11/$AK$24 -> #DIV/0! | AZ11: =E11+I11+M11+Q11+U11+Y11+AC11+AG11+AK11+AO11+AS11+AW11 -> 163716550 | BA11: =AVERAGE(F11,J11,N11,R11,V11,Z11,AD11,AH11,AL11,AP11,AT11,AX11) -> #DIV/0! | BB11: =AVERAGE(G11,K11,O11,S11,W11,AA11,AE11,AI11,AM11,AQ11,AU11,AY11) -> #DIV/0! | BC11: =E11+I11+M11 -> 163716550 | BD11: =Q11+U11+Y11 -> 0 | BE11: =AC11+AG11+AK11 -> 0 | BF11: =AO11+AS11+AW11 -> 0
B12: =B11+1 -> 6 | C12: HRD,GA & Legal | D12: =NPA!D12+NES!D12+'2026-PKL NPA'!D12+'2026- Harian NES'!D12+'2026-Harian NPA'!D12+'2026-LPK MKS NPA'!D12+'2026-LPK MKM NPA'!D12+'2026-LPK DKP NPA '!D12+'2026-LPK CTPS NPA'!D12+'2026-LPK CDB NPA'!D12+'2026-OS CTPS NPA'!D12+'2026-OS CDB NPA'!D12 -> 22 | E12: =NPA!E12+NES!E12+'2026-PKL NPA'!E12+'2026- Harian NES'!E12+'2026-Harian NPA'!E12+'2026-LPK MKS NPA'!E12+'2026-LPK MKM NPA'!E12+'2026-LPK DKP NPA '!E12+'2026-LPK CTPS NPA'!E12+'2026-LPK CDB NPA'!E12+'2026-OS CTPS NPA'!E12+'2026-OS CDB NPA'!E12 -> 163588708 | F12: =D12/$D$24 -> 0.067692308 | G12: =E12/$E$24 -> 0.0654965 | H12: =NPA!H12+NES!H12+'2026-PKL NPA'!H12+'2026- Harian NES'!H12+'2026-Harian NPA'!H12+'2026-LPK MKS NPA'!H12+'2026-LPK MKM NPA'!H12+'2026-LPK DKP NPA '!H12+'2026-LPK CTPS NPA'!H12+'2026-LPK CDB NPA'!H12+'2026-OS CTPS NPA'!H12+'2026-OS CDB NPA'!H12 -> 20 | I12: =NPA!I12+NES!I12+'2026-PKL NPA'!I12+'2026- Harian NES'!I12+'2026-Harian NPA'!I12+'2026-LPK MKS NPA'!I12+'2026-LPK MKM NPA'!I12+'2026-LPK DKP NPA '!I12+'2026-LPK CTPS NPA'!I12+'2026-LPK CDB NPA'!I12+'2026-OS CTPS NPA'!I12+'2026-OS CDB NPA'!I12 -> 158052790 | J12: =H12/$H$24 -> 0.064308682 | K12: =I12/$I$24 -> 0.067890102 | L12: =NPA!L12+NES!L12+'2026-PKL NPA'!L12+'2026- Harian NES'!L12+'2026-Harian NPA'!L12+'2026-LPK MKS NPA'!L12+'2026-LPK MKM NPA'!L12+'2026-LPK DKP NPA '!L12+'2026-LPK CTPS NPA'!L12+'2026-LPK CDB NPA'!L12+'2026-OS CTPS NPA'!L12+'2026-OS CDB NPA'!L12 -> 20 | M12: =NPA!M12+NES!M12+'2026-PKL NPA'!M12+'2026- Harian NES'!M12+'2026-Harian NPA'!M12+'2026-LPK MKS NPA'!M12+'2026-LPK MKM NPA'!M12+'2026-LPK DKP NPA '!M12+'2026-LPK CTPS NPA'!M12+'2026-LPK CDB NPA'!M12+'2026-OS CTPS NPA'!M12+'2026-OS CDB NPA'!M12 -> 147062086 | N12: =L12/$L$24 -> 0.064308682 | O12: =M12/$M$24 -> 0.067810253 | P12: =NPA!P12+NES!P12+'2026-PKL NPA'!P12+'2026- Harian NES'!P12+'2026-Harian NPA'!P12+'2026-LPK MKS NPA'!P12+'2026-LPK MKM NPA'!P12+'2026-LPK DKP NPA '!P12+'2026-LPK CTPS NPA'!P12+'2026-LPK CDB NPA'!P12+'2026-OS CTPS NPA'!P12+'2026-OS CDB NPA'!P12 -> 0 | Q12: =NPA!Q12+NES!Q12+'2026-PKL NPA'!Q12+'2026- Harian NES'!Q12+'2026-Harian NPA'!Q12+'2026-LPK MKS NPA'!Q12+'2026-LPK MKM NPA'!Q12+'2026-LPK DKP NPA '!Q12+'2026-LPK CTPS NPA'!Q12+'2026-LPK CDB NPA'!Q12+'2026-OS CTPS NPA'!Q12+'2026-OS CDB NPA'!Q12 -> 0 | R12: =P12/$P$24 -> #DIV/0! | S12: =Q12/$Q$24 -> #DIV/0! | T12: =NPA!T12+NES!T12+'2026-PKL NPA'!T12+'2026- Harian NES'!T12+'2026-Harian NPA'!T12+'2026-LPK MKS NPA'!T12+'2026-LPK MKM NPA'!T12+'2026-LPK DKP NPA '!T12+'2026-LPK CTPS NPA'!T12+'2026-LPK CDB NPA'!T12+'2026-OS CTPS NPA'!T12+'2026-OS CDB NPA'!T12 -> 0 | U12: =NPA!U12+NES!U12+'2026-PKL NPA'!U12+'2026- Harian NES'!U12+'2026-Harian NPA'!U12+'2026-LPK MKS NPA'!U12+'2026-LPK MKM NPA'!U12+'2026-LPK DKP NPA '!U12+'2026-LPK CTPS NPA'!U12+'2026-LPK CDB NPA'!U12+'2026-OS CTPS NPA'!U12+'2026-OS CDB NPA'!U12 -> 0 | V12: =T12/$T$24 -> #DIV/0! | W12: =U12/$U$24 -> #DIV/0! | X12: =NPA!X12+NES!X12+'2026-PKL NPA'!X12+'2026- Harian NES'!X12+'2026-Harian NPA'!X12+'2026-LPK MKS NPA'!X12+'2026-LPK MKM NPA'!X12+'2026-LPK DKP NPA '!X12+'2026-LPK CTPS NPA'!X12+'2026-LPK CDB NPA'!X12+'2026-OS CTPS NPA'!X12+'2026-OS CDB NPA'!X12 -> 0 | Y12: =NPA!Y12+NES!Y12+'2026-PKL NPA'!Y12+'2026- Harian NES'!Y12+'2026-Harian NPA'!Y12+'2026-LPK MKS NPA'!Y12+'2026-LPK MKM NPA'!Y12+'2026-LPK DKP NPA '!Y12+'2026-LPK CTPS NPA'!Y12+'2026-LPK CDB NPA'!Y12+'2026-OS CTPS NPA'!Y12+'2026-OS CDB NPA'!Y12 -> 0 | Z12: =X12/$X$24 -> #DIV/0! | AA12: =Y12/$Y$24 -> #DIV/0! | AB12: =NPA!AB12+NES!AB12+'2026-PKL NPA'!AB12+'2026- Harian NES'!AB12+'2026-Harian NPA'!AB12+'2026-LPK MKS NPA'!AB12+'2026-LPK MKM NPA'!AB12+'2026-LPK DKP NPA '!AB12+'2026-LPK CTPS NPA'!AB12+'2026-LPK CDB NPA'!AB12+'2026-OS CTPS NPA'!AB12+'2026-OS CDB NPA'!AB12 -> 0 | AC12: =NPA!AC12+NES!AC12+'2026-PKL NPA'!AC12+'2026- Harian NES'!AC12+'2026-Harian NPA'!AC12+'2026-LPK MKS NPA'!AC12+'2026-LPK MKM NPA'!AC12+'2026-LPK DKP NPA '!AC12+'2026-LPK CTPS NPA'!AC12+'2026-LPK CDB NPA'!AC12+'2026-OS CTPS NPA'!AC12+'2026-OS CDB NPA'!AC12 -> 0 | AD12: =AB12/$AB$24 -> #DIV/0! | AE12: =AC12/$AC$24 -> #DIV/0! | AF12: =NPA!AF12+NES!AF12+'2026-PKL NPA'!AF12+'2026- Harian NES'!AF12+'2026-Harian NPA'!AF12+'2026-LPK MKS NPA'!AF12+'2026-LPK MKM NPA'!AF12+'2026-LPK DKP NPA '!AF12+'2026-LPK CTPS NPA'!AF12+'2026-LPK CDB NPA'!AF12+'2026-OS CTPS NPA'!AF12+'2026-OS CDB NPA'!AF12 -> 0 | AG12: =NPA!AG12+NES!AG12+'2026-PKL NPA'!AG12+'2026- Harian NES'!AG12+'2026-Harian NPA'!AG12+'2026-LPK MKS NPA'!AG12+'2026-LPK MKM NPA'!AG12+'2026-LPK DKP NPA '!AG12+'2026-LPK CTPS NPA'!AG12+'2026-LPK CDB NPA'!AG12+'2026-OS CTPS NPA'!AG12+'2026-OS CDB NPA'!AG12 -> 0 | AH12: =AF12/$AF$24 -> #DIV/0! | AI12: =AG12/$AG$24 -> #DIV/0! | AJ12: =NPA!AJ12+NES!AJ12+'2026-PKL NPA'!AJ12+'2026- Harian NES'!AJ12+'2026-Harian NPA'!AJ12+'2026-LPK MKS NPA'!AJ12+'2026-LPK MKM NPA'!AJ12+'2026-LPK DKP NPA '!AJ12+'2026-LPK CTPS NPA'!AJ12+'2026-LPK CDB NPA'!AJ12+'2026-OS CTPS NPA'!AJ12+'2026-OS CDB NPA'!AJ12 -> 0 | AK12: =NPA!AK12+NES!AK12+'2026-PKL NPA'!AK12+'2026- Harian NES'!AK12+'2026-Harian NPA'!AK12+'2026-LPK MKS NPA'!AK12+'2026-LPK MKM NPA'!AK12+'2026-LPK DKP NPA '!AK12+'2026-LPK CTPS NPA'!AK12+'2026-LPK CDB NPA'!AK12+'2026-OS CTPS NPA'!AK12+'2026-OS CDB NPA'!AK12 -> 0 | AL12: =AJ12/$AJ$24 -> #DIV/0! | AM12: =AK12/$AK$24 -> #DIV/0! | AN12: =NPA!AN12+NES!AN12+'2026-PKL NPA'!AN12+'2026- Harian NES'!AN12+'2026-Harian NPA'!AN12+'2026-LPK MKS NPA'!AN12+'2026-LPK MKM NPA'!AN12+'2026-LPK DKP NPA '!AN12+'2026-LPK CTPS NPA'!AN12+'2026-LPK CDB NPA'!AN12+'2026-OS CTPS NPA'!AN12+'2026-OS CDB NPA'!AN12 -> 0 | AO12: =NPA!AO12+NES!AO12+'2026-PKL NPA'!AO12+'2026- Harian NES'!AO12+'2026-Harian NPA'!AO12+'2026-LPK MKS NPA'!AO12+'2026-LPK MKM NPA'!AO12+'2026-LPK DKP NPA '!AO12+'2026-LPK CTPS NPA'!AO12+'2026-LPK CDB NPA'!AO12+'2026-OS CTPS NPA'!AO12+'2026-OS CDB NPA'!AO12 -> 0 | AP12: =AN12/$AN$24 -> #DIV/0! | AQ12: =AO12/$AO$24 -> #DIV/0! | AR12: =NPA!AR12+NES!AR12+'2026-PKL NPA'!AR12+'2026- Harian NES'!AR12+'2026-Harian NPA'!AR12+'2026-LPK MKS NPA'!AR12+'2026-LPK MKM NPA'!AR12+'2026-LPK DKP NPA '!AR12+'2026-LPK CTPS NPA'!AR12+'2026-LPK CDB NPA'!AR12+'2026-OS CTPS NPA'!AR12+'2026-OS CDB NPA'!AR12 -> 0 | AS12: =NPA!AS12+NES!AS12+'2026-PKL NPA'!AS12+'2026- Harian NES'!AS12+'2026-Harian NPA'!AS12+'2026-LPK MKS NPA'!AS12+'2026-LPK MKM NPA'!AS12+'2026-LPK DKP NPA '!AS12+'2026-LPK CTPS NPA'!AS12+'2026-LPK CDB NPA'!AS12+'2026-OS CTPS NPA'!AS12+'2026-OS CDB NPA'!AS12 -> 0 | AT12: =AR12/$AR$24 -> #DIV/0! | AU12: =AS12/$AS$24 -> #DIV/0! | AV12: =NPA!AV12+NES!AV12+'2026-PKL NPA'!AV12+'2026- Harian NES'!AV12+'2026-Harian NPA'!AV12+'2026-LPK MKS NPA'!AV12+'2026-LPK MKM NPA'!AV12+'2026-LPK DKP NPA '!AV12+'2026-LPK CTPS NPA'!AV12+'2026-LPK CDB NPA'!AV12+'2026-OS CTPS NPA'!AV12+'2026-OS CDB NPA'!AV12 -> 0 | AW12: =NPA!AW12+NES!AW12+'2026-PKL NPA'!AW12+'2026- Harian NES'!AW12+'2026-Harian NPA'!AW12+'2026-LPK MKS NPA'!AW12+'2026-LPK MKM NPA'!AW12+'2026-LPK DKP NPA '!AW12+'2026-LPK CTPS NPA'!AW12+'2026-LPK CDB NPA'!AW12+'2026-OS CTPS NPA'!AW12+'2026-OS CDB NPA'!AW12 -> 0 | AX12: =AV12/$AJ$24 -> #DIV/0! | AY12: =AW12/$AK$24 -> #DIV/0! | AZ12: =E12+I12+M12+Q12+U12+Y12+AC12+AG12+AK12+AO12+AS12+AW12 -> 468703584 | BA12: =AVERAGE(F12,J12,N12,R12,V12,Z12,AD12,AH12,AL12,AP12,AT12,AX12) -> #DIV/0! | BB12: =AVERAGE(G12,K12,O12,S12,W12,AA12,AE12,AI12,AM12,AQ12,AU12,AY12) -> #DIV/0! | BC12: =E12+I12+M12 -> 468703584 | BD12: =Q12+U12+Y12 -> 0 | BE12: =AC12+AG12+AK12 -> 0 | BF12: =AO12+AS12+AW12 -> 0
B13: =B12+1 -> 7 | C13: HRD,GA & Legal (SECURITY) | D13: =NPA!D13+NES!D13+'2026-PKL NPA'!D13+'2026- Harian NES'!D13+'2026-Harian NPA'!D13+'2026-LPK MKS NPA'!D13+'2026-LPK MKM NPA'!D13+'2026-LPK DKP NPA '!D13+'2026-LPK CTPS NPA'!D13+'2026-LPK CDB NPA'!D13+'2026-OS CTPS NPA'!D13+'2026-OS CDB NPA'!D13 -> 15 | E13: =NPA!E13+NES!E13+'2026-PKL NPA'!E13+'2026- Harian NES'!E13+'2026-Harian NPA'!E13+'2026-LPK MKS NPA'!E13+'2026-LPK MKM NPA'!E13+'2026-LPK DKP NPA '!E13+'2026-LPK CTPS NPA'!E13+'2026-LPK CDB NPA'!E13+'2026-OS CTPS NPA'!E13+'2026-OS CDB NPA'!E13 -> 143029030 | F13: =D13/$D$24 -> 0.046153846 | G13: =E13/$E$24 -> 0.057264961 | H13: =NPA!H13+NES!H13+'2026-PKL NPA'!H13+'2026- Harian NES'!H13+'2026-Harian NPA'!H13+'2026-LPK MKS NPA'!H13+'2026-LPK MKM NPA'!H13+'2026-LPK DKP NPA '!H13+'2026-LPK CTPS NPA'!H13+'2026-LPK CDB NPA'!H13+'2026-OS CTPS NPA'!H13+'2026-OS CDB NPA'!H13 -> 15 | I13: =NPA!I13+NES!I13+'2026-PKL NPA'!I13+'2026- Harian NES'!I13+'2026-Harian NPA'!I13+'2026-LPK MKS NPA'!I13+'2026-LPK MKM NPA'!I13+'2026-LPK DKP NPA '!I13+'2026-LPK CTPS NPA'!I13+'2026-LPK CDB NPA'!I13+'2026-OS CTPS NPA'!I13+'2026-OS CDB NPA'!I13 -> 131419610 | J13: =H13/$H$24 -> 0.048231511 | K13: =I13/$I$24 -> 0.056450068 | L13: =NPA!L13+NES!L13+'2026-PKL NPA'!L13+'2026- Harian NES'!L13+'2026-Harian NPA'!L13+'2026-LPK MKS NPA'!L13+'2026-LPK MKM NPA'!L13+'2026-LPK DKP NPA '!L13+'2026-LPK CTPS NPA'!L13+'2026-LPK CDB NPA'!L13+'2026-OS CTPS NPA'!L13+'2026-OS CDB NPA'!L13 -> 15 | M13: =NPA!M13+NES!M13+'2026-PKL NPA'!M13+'2026- Harian NES'!M13+'2026-Harian NPA'!M13+'2026-LPK MKS NPA'!M13+'2026-LPK MKM NPA'!M13+'2026-LPK DKP NPA '!M13+'2026-LPK CTPS NPA'!M13+'2026-LPK CDB NPA'!M13+'2026-OS CTPS NPA'!M13+'2026-OS CDB NPA'!M13 -> 137778778 | N13: =L13/$L$24 -> 0.048231511 | O13: =M13/$M$24 -> 0.063529725 | P13: =NPA!P13+NES!P13+'2026-PKL NPA'!P13+'2026- Harian NES'!P13+'2026-Harian NPA'!P13+'2026-LPK MKS NPA'!P13+'2026-LPK MKM NPA'!P13+'2026-LPK DKP NPA '!P13+'2026-LPK CTPS NPA'!P13+'2026-LPK CDB NPA'!P13+'2026-OS CTPS NPA'!P13+'2026-OS CDB NPA'!P13 -> 0 | Q13: =NPA!Q13+NES!Q13+'2026-PKL NPA'!Q13+'2026- Harian NES'!Q13+'2026-Harian NPA'!Q13+'2026-LPK MKS NPA'!Q13+'2026-LPK MKM NPA'!Q13+'2026-LPK DKP NPA '!Q13+'2026-LPK CTPS NPA'!Q13+'2026-LPK CDB NPA'!Q13+'2026-OS CTPS NPA'!Q13+'2026-OS CDB NPA'!Q13 -> 0 | R13: =P13/$P$24 -> #DIV/0! | S13: =Q13/$Q$24 -> #DIV/0! | T13: =NPA!T13+NES!T13+'2026-PKL NPA'!T13+'2026- Harian NES'!T13+'2026-Harian NPA'!T13+'2026-LPK MKS NPA'!T13+'2026-LPK MKM NPA'!T13+'2026-LPK DKP NPA '!T13+'2026-LPK CTPS NPA'!T13+'2026-LPK CDB NPA'!T13+'2026-OS CTPS NPA'!T13+'2026-OS CDB NPA'!T13 -> 0 | U13: =NPA!U13+NES!U13+'2026-PKL NPA'!U13+'2026- Harian NES'!U13+'2026-Harian NPA'!U13+'2026-LPK MKS NPA'!U13+'2026-LPK MKM NPA'!U13+'2026-LPK DKP NPA '!U13+'2026-LPK CTPS NPA'!U13+'2026-LPK CDB NPA'!U13+'2026-OS CTPS NPA'!U13+'2026-OS CDB NPA'!U13 -> 0 | V13: =T13/$T$24 -> #DIV/0! | W13: =U13/$U$24 -> #DIV/0! | X13: =NPA!X13+NES!X13+'2026-PKL NPA'!X13+'2026- Harian NES'!X13+'2026-Harian NPA'!X13+'2026-LPK MKS NPA'!X13+'2026-LPK MKM NPA'!X13+'2026-LPK DKP NPA '!X13+'2026-LPK CTPS NPA'!X13+'2026-LPK CDB NPA'!X13+'2026-OS CTPS NPA'!X13+'2026-OS CDB NPA'!X13 -> 0 | Y13: =NPA!Y13+NES!Y13+'2026-PKL NPA'!Y13+'2026- Harian NES'!Y13+'2026-Harian NPA'!Y13+'2026-LPK MKS NPA'!Y13+'2026-LPK MKM NPA'!Y13+'2026-LPK DKP NPA '!Y13+'2026-LPK CTPS NPA'!Y13+'2026-LPK CDB NPA'!Y13+'2026-OS CTPS NPA'!Y13+'2026-OS CDB NPA'!Y13 -> 0 | Z13: =X13/$X$24 -> #DIV/0! | AA13: =Y13/$Y$24 -> #DIV/0! | AB13: =NPA!AB13+NES!AB13+'2026-PKL NPA'!AB13+'2026- Harian NES'!AB13+'2026-Harian NPA'!AB13+'2026-LPK MKS NPA'!AB13+'2026-LPK MKM NPA'!AB13+'2026-LPK DKP NPA '!AB13+'2026-LPK CTPS NPA'!AB13+'2026-LPK CDB NPA'!AB13+'2026-OS CTPS NPA'!AB13+'2026-OS CDB NPA'!AB13 -> 0 | AC13: =NPA!AC13+NES!AC13+'2026-PKL NPA'!AC13+'2026- Harian NES'!AC13+'2026-Harian NPA'!AC13+'2026-LPK MKS NPA'!AC13+'2026-LPK MKM NPA'!AC13+'2026-LPK DKP NPA '!AC13+'2026-LPK CTPS NPA'!AC13+'2026-LPK CDB NPA'!AC13+'2026-OS CTPS NPA'!AC13+'2026-OS CDB NPA'!AC13 -> 0 | AD13: =AB13/$AB$24 -> #DIV/0! | AE13: =AC13/$AC$24 -> #DIV/0! | AF13: =NPA!AF13+NES!AF13+'2026-PKL NPA'!AF13+'2026- Harian NES'!AF13+'2026-Harian NPA'!AF13+'2026-LPK MKS NPA'!AF13+'2026-LPK MKM NPA'!AF13+'2026-LPK DKP NPA '!AF13+'2026-LPK CTPS NPA'!AF13+'2026-LPK CDB NPA'!AF13+'2026-OS CTPS NPA'!AF13+'2026-OS CDB NPA'!AF13 -> 0 | AG13: =NPA!AG13+NES!AG13+'2026-PKL NPA'!AG13+'2026- Harian NES'!AG13+'2026-Harian NPA'!AG13+'2026-LPK MKS NPA'!AG13+'2026-LPK MKM NPA'!AG13+'2026-LPK DKP NPA '!AG13+'2026-LPK CTPS NPA'!AG13+'2026-LPK CDB NPA'!AG13+'2026-OS CTPS NPA'!AG13+'2026-OS CDB NPA'!AG13 -> 0 | AH13: =AF13/$AF$24 -> #DIV/0! | AI13: =AG13/$AG$24 -> #DIV/0! | AJ13: =NPA!AJ13+NES!AJ13+'2026-PKL NPA'!AJ13+'2026- Harian NES'!AJ13+'2026-Harian NPA'!AJ13+'2026-LPK MKS NPA'!AJ13+'2026-LPK MKM NPA'!AJ13+'2026-LPK DKP NPA '!AJ13+'2026-LPK CTPS NPA'!AJ13+'2026-LPK CDB NPA'!AJ13+'2026-OS CTPS NPA'!AJ13+'2026-OS CDB NPA'!AJ13 -> 0 | AK13: =NPA!AK13+NES!AK13+'2026-PKL NPA'!AK13+'2026- Harian NES'!AK13+'2026-Harian NPA'!AK13+'2026-LPK MKS NPA'!AK13+'2026-LPK MKM NPA'!AK13+'2026-LPK DKP NPA '!AK13+'2026-LPK CTPS NPA'!AK13+'2026-LPK CDB NPA'!AK13+'2026-OS CTPS NPA'!AK13+'2026-OS CDB NPA'!AK13 -> 0 | AL13: =AJ13/$AJ$24 -> #DIV/0! | AM13: =AK13/$AK$24 -> #DIV/0! | AN13: =NPA!AN13+NES!AN13+'2026-PKL NPA'!AN13+'2026- Harian NES'!AN13+'2026-Harian NPA'!AN13+'2026-LPK MKS NPA'!AN13+'2026-LPK MKM NPA'!AN13+'2026-LPK DKP NPA '!AN13+'2026-LPK CTPS NPA'!AN13+'2026-LPK CDB NPA'!AN13+'2026-OS CTPS NPA'!AN13+'2026-OS CDB NPA'!AN13 -> 0 | AO13: =NPA!AO13+NES!AO13+'2026-PKL NPA'!AO13+'2026- Harian NES'!AO13+'2026-Harian NPA'!AO13+'2026-LPK MKS NPA'!AO13+'2026-LPK MKM NPA'!AO13+'2026-LPK DKP NPA '!AO13+'2026-LPK CTPS NPA'!AO13+'2026-LPK CDB NPA'!AO13+'2026-OS CTPS NPA'!AO13+'2026-OS CDB NPA'!AO13 -> 0 | AP13: =AN13/$AN$24 -> #DIV/0! | AQ13: =AO13/$AO$24 -> #DIV/0! | AR13: =NPA!AR13+NES!AR13+'2026-PKL NPA'!AR13+'2026- Harian NES'!AR13+'2026-Harian NPA'!AR13+'2026-LPK MKS NPA'!AR13+'2026-LPK MKM NPA'!AR13+'2026-LPK DKP NPA '!AR13+'2026-LPK CTPS NPA'!AR13+'2026-LPK CDB NPA'!AR13+'2026-OS CTPS NPA'!AR13+'2026-OS CDB NPA'!AR13 -> 0 | AS13: =NPA!AS13+NES!AS13+'2026-PKL NPA'!AS13+'2026- Harian NES'!AS13+'2026-Harian NPA'!AS13+'2026-LPK MKS NPA'!AS13+'2026-LPK MKM NPA'!AS13+'2026-LPK DKP NPA '!AS13+'2026-LPK CTPS NPA'!AS13+'2026-LPK CDB NPA'!AS13+'2026-OS CTPS NPA'!AS13+'2026-OS CDB NPA'!AS13 -> 0 | AT13: =AR13/$AR$24 -> #DIV/0! | AU13: =AS13/$AS$24 -> #DIV/0! | AV13: =NPA!AV13+NES!AV13+'2026-PKL NPA'!AV13+'2026- Harian NES'!AV13+'2026-Harian NPA'!AV13+'2026-LPK MKS NPA'!AV13+'2026-LPK MKM NPA'!AV13+'2026-LPK DKP NPA '!AV13+'2026-LPK CTPS NPA'!AV13+'2026-LPK CDB NPA'!AV13+'2026-OS CTPS NPA'!AV13+'2026-OS CDB NPA'!AV13 -> 0 | AW13: =NPA!AW13+NES!AW13+'2026-PKL NPA'!AW13+'2026- Harian NES'!AW13+'2026-Harian NPA'!AW13+'2026-LPK MKS NPA'!AW13+'2026-LPK MKM NPA'!AW13+'2026-LPK DKP NPA '!AW13+'2026-LPK CTPS NPA'!AW13+'2026-LPK CDB NPA'!AW13+'2026-OS CTPS NPA'!AW13+'2026-OS CDB NPA'!AW13 -> 0 | AX13: =AV13/$AJ$24 -> #DIV/0! | AY13: =AW13/$AK$24 -> #DIV/0! | BA13: =AVERAGE(F13,J13,N13,R13,V13,Z13,AD13,AH13,AL13,AP13,AT13,AX13) -> #DIV/0! | BB13: =AVERAGE(G13,K13,O13,S13,W13,AA13,AE13,AI13,AM13,AQ13,AU13,AY13) -> #DIV/0! | BC13: =E13+I13+M13 -> 412227418 | BD13: =Q13+U13+Y13 -> 0 | BE13: =AC13+AG13+AK13 -> 0 | BF13: =AO13+AS13+AW13 -> 0
B14: =B13+1 -> 8 | C14: MR, QC & HSE | D14: =NPA!D14+NES!D14+'2026-PKL NPA'!D14+'2026- Harian NES'!D14+'2026-Harian NPA'!D14+'2026-LPK MKS NPA'!D14+'2026-LPK MKM NPA'!D14+'2026-LPK DKP NPA '!D14+'2026-LPK CTPS NPA'!D14+'2026-LPK CDB NPA'!D14+'2026-OS CTPS NPA'!D14+'2026-OS CDB NPA'!D14 -> 14 | E14: =NPA!E14+NES!E14+'2026-PKL NPA'!E14+'2026- Harian NES'!E14+'2026-Harian NPA'!E14+'2026-LPK MKS NPA'!E14+'2026-LPK MKM NPA'!E14+'2026-LPK DKP NPA '!E14+'2026-LPK CTPS NPA'!E14+'2026-LPK CDB NPA'!E14+'2026-OS CTPS NPA'!E14+'2026-OS CDB NPA'!E14 -> 108270782 | F14: =D14/$D$24 -> 0.043076923 | G14: =E14/$E$24 -> 0.043348697 | H14: =NPA!H14+NES!H14+'2026-PKL NPA'!H14+'2026- Harian NES'!H14+'2026-Harian NPA'!H14+'2026-LPK MKS NPA'!H14+'2026-LPK MKM NPA'!H14+'2026-LPK DKP NPA '!H14+'2026-LPK CTPS NPA'!H14+'2026-LPK CDB NPA'!H14+'2026-OS CTPS NPA'!H14+'2026-OS CDB NPA'!H14 -> 14 | I14: =NPA!I14+NES!I14+'2026-PKL NPA'!I14+'2026- Harian NES'!I14+'2026-Harian NPA'!I14+'2026-LPK MKS NPA'!I14+'2026-LPK MKM NPA'!I14+'2026-LPK DKP NPA '!I14+'2026-LPK CTPS NPA'!I14+'2026-LPK CDB NPA'!I14+'2026-OS CTPS NPA'!I14+'2026-OS CDB NPA'!I14 -> 106249244 | J14: =H14/$H$24 -> 0.045016077 | K14: =I14/$I$24 -> 0.045638372 | L14: =NPA!L14+NES!L14+'2026-PKL NPA'!L14+'2026- Harian NES'!L14+'2026-Harian NPA'!L14+'2026-LPK MKS NPA'!L14+'2026-LPK MKM NPA'!L14+'2026-LPK DKP NPA '!L14+'2026-LPK CTPS NPA'!L14+'2026-LPK CDB NPA'!L14+'2026-OS CTPS NPA'!L14+'2026-OS CDB NPA'!L14 -> 13 | M14: =NPA!M14+NES!M14+'2026-PKL NPA'!M14+'2026- Harian NES'!M14+'2026-Harian NPA'!M14+'2026-LPK MKS NPA'!M14+'2026-LPK MKM NPA'!M14+'2026-LPK DKP NPA '!M14+'2026-LPK CTPS NPA'!M14+'2026-LPK CDB NPA'!M14+'2026-OS CTPS NPA'!M14+'2026-OS CDB NPA'!M14 -> 96233945 | N14: =L14/$L$24 -> 0.041800643 | O14: =M14/$M$24 -> 0.044373423 | P14: =NPA!P14+NES!P14+'2026-PKL NPA'!P14+'2026- Harian NES'!P14+'2026-Harian NPA'!P14+'2026-LPK MKS NPA'!P14+'2026-LPK MKM NPA'!P14+'2026-LPK DKP NPA '!P14+'2026-LPK CTPS NPA'!P14+'2026-LPK CDB NPA'!P14+'2026-OS CTPS NPA'!P14+'2026-OS CDB NPA'!P14 -> 0 | Q14: =NPA!Q14+NES!Q14+'2026-PKL NPA'!Q14+'2026- Harian NES'!Q14+'2026-Harian NPA'!Q14+'2026-LPK MKS NPA'!Q14+'2026-LPK MKM NPA'!Q14+'2026-LPK DKP NPA '!Q14+'2026-LPK CTPS NPA'!Q14+'2026-LPK CDB NPA'!Q14+'2026-OS CTPS NPA'!Q14+'2026-OS CDB NPA'!Q14 -> 0 | R14: =P14/$P$24 -> #DIV/0! | S14: =Q14/$Q$24 -> #DIV/0! | T14: =NPA!T14+NES!T14+'2026-PKL NPA'!T14+'2026- Harian NES'!T14+'2026-Harian NPA'!T14+'2026-LPK MKS NPA'!T14+'2026-LPK MKM NPA'!T14+'2026-LPK DKP NPA '!T14+'2026-LPK CTPS NPA'!T14+'2026-LPK CDB NPA'!T14+'2026-OS CTPS NPA'!T14+'2026-OS CDB NPA'!T14 -> 0 | U14: =NPA!U14+NES!U14+'2026-PKL NPA'!U14+'2026- Harian NES'!U14+'2026-Harian NPA'!U14+'2026-LPK MKS NPA'!U14+'2026-LPK MKM NPA'!U14+'2026-LPK DKP NPA '!U14+'2026-LPK CTPS NPA'!U14+'2026-LPK CDB NPA'!U14+'2026-OS CTPS NPA'!U14+'2026-OS CDB NPA'!U14 -> 0 | V14: =T14/$T$24 -> #DIV/0! | W14: =U14/$U$24 -> #DIV/0! | X14: =NPA!X14+NES!X14+'2026-PKL NPA'!X14+'2026- Harian NES'!X14+'2026-Harian NPA'!X14+'2026-LPK MKS NPA'!X14+'2026-LPK MKM NPA'!X14+'2026-LPK DKP NPA '!X14+'2026-LPK CTPS NPA'!X14+'2026-LPK CDB NPA'!X14+'2026-OS CTPS NPA'!X14+'2026-OS CDB NPA'!X14 -> 0 | Y14: =NPA!Y14+NES!Y14+'2026-PKL NPA'!Y14+'2026- Harian NES'!Y14+'2026-Harian NPA'!Y14+'2026-LPK MKS NPA'!Y14+'2026-LPK MKM NPA'!Y14+'2026-LPK DKP NPA '!Y14+'2026-LPK CTPS NPA'!Y14+'2026-LPK CDB NPA'!Y14+'2026-OS CTPS NPA'!Y14+'2026-OS CDB NPA'!Y14 -> 0 | Z14: =X14/$X$24 -> #DIV/0! | AA14: =Y14/$Y$24 -> #DIV/0! | AB14: =NPA!AB14+NES!AB14+'2026-PKL NPA'!AB14+'2026- Harian NES'!AB14+'2026-Harian NPA'!AB14+'2026-LPK MKS NPA'!AB14+'2026-LPK MKM NPA'!AB14+'2026-LPK DKP NPA '!AB14+'2026-LPK CTPS NPA'!AB14+'2026-LPK CDB NPA'!AB14+'2026-OS CTPS NPA'!AB14+'2026-OS CDB NPA'!AB14 -> 0 | AC14: =NPA!AC14+NES!AC14+'2026-PKL NPA'!AC14+'2026- Harian NES'!AC14+'2026-Harian NPA'!AC14+'2026-LPK MKS NPA'!AC14+'2026-LPK MKM NPA'!AC14+'2026-LPK DKP NPA '!AC14+'2026-LPK CTPS NPA'!AC14+'2026-LPK CDB NPA'!AC14+'2026-OS CTPS NPA'!AC14+'2026-OS CDB NPA'!AC14 -> 0 | AD14: =AB14/$AB$24 -> #DIV/0! | AE14: =AC14/$AC$24 -> #DIV/0! | AF14: =NPA!AF14+NES!AF14+'2026-PKL NPA'!AF14+'2026- Harian NES'!AF14+'2026-Harian NPA'!AF14+'2026-LPK MKS NPA'!AF14+'2026-LPK MKM NPA'!AF14+'2026-LPK DKP NPA '!AF14+'2026-LPK CTPS NPA'!AF14+'2026-LPK CDB NPA'!AF14+'2026-OS CTPS NPA'!AF14+'2026-OS CDB NPA'!AF14 -> 0 | AG14: =NPA!AG14+NES!AG14+'2026-PKL NPA'!AG14+'2026- Harian NES'!AG14+'2026-Harian NPA'!AG14+'2026-LPK MKS NPA'!AG14+'2026-LPK MKM NPA'!AG14+'2026-LPK DKP NPA '!AG14+'2026-LPK CTPS NPA'!AG14+'2026-LPK CDB NPA'!AG14+'2026-OS CTPS NPA'!AG14+'2026-OS CDB NPA'!AG14 -> 0 | AH14: =AF14/$AF$24 -> #DIV/0! | AI14: =AG14/$AG$24 -> #DIV/0! | AJ14: =NPA!AJ14+NES!AJ14+'2026-PKL NPA'!AJ14+'2026- Harian NES'!AJ14+'2026-Harian NPA'!AJ14+'2026-LPK MKS NPA'!AJ14+'2026-LPK MKM NPA'!AJ14+'2026-LPK DKP NPA '!AJ14+'2026-LPK CTPS NPA'!AJ14+'2026-LPK CDB NPA'!AJ14+'2026-OS CTPS NPA'!AJ14+'2026-OS CDB NPA'!AJ14 -> 0 | AK14: =NPA!AK14+NES!AK14+'2026-PKL NPA'!AK14+'2026- Harian NES'!AK14+'2026-Harian NPA'!AK14+'2026-LPK MKS NPA'!AK14+'2026-LPK MKM NPA'!AK14+'2026-LPK DKP NPA '!AK14+'2026-LPK CTPS NPA'!AK14+'2026-LPK CDB NPA'!AK14+'2026-OS CTPS NPA'!AK14+'2026-OS CDB NPA'!AK14 -> 0 | AL14: =AJ14/$AJ$24 -> #DIV/0! | AM14: =AK14/$AK$24 -> #DIV/0! | AN14: =NPA!AN14+NES!AN14+'2026-PKL NPA'!AN14+'2026- Harian NES'!AN14+'2026-Harian NPA'!AN14+'2026-LPK MKS NPA'!AN14+'2026-LPK MKM NPA'!AN14+'2026-LPK DKP NPA '!AN14+'2026-LPK CTPS NPA'!AN14+'2026-LPK CDB NPA'!AN14+'2026-OS CTPS NPA'!AN14+'2026-OS CDB NPA'!AN14 -> 0 | AO14: =NPA!AO14+NES!AO14+'2026-PKL NPA'!AO14+'2026- Harian NES'!AO14+'2026-Harian NPA'!AO14+'2026-LPK MKS NPA'!AO14+'2026-LPK MKM NPA'!AO14+'2026-LPK DKP NPA '!AO14+'2026-LPK CTPS NPA'!AO14+'2026-LPK CDB NPA'!AO14+'2026-OS CTPS NPA'!AO14+'2026-OS CDB NPA'!AO14 -> 0 | AP14: =AN14/$AN$24 -> #DIV/0! | AQ14: =AO14/$AO$24 -> #DIV/0! | AR14: =NPA!AR14+NES!AR14+'2026-PKL NPA'!AR14+'2026- Harian NES'!AR14+'2026-Harian NPA'!AR14+'2026-LPK MKS NPA'!AR14+'2026-LPK MKM NPA'!AR14+'2026-LPK DKP NPA '!AR14+'2026-LPK CTPS NPA'!AR14+'2026-LPK CDB NPA'!AR14+'2026-OS CTPS NPA'!AR14+'2026-OS CDB NPA'!AR14 -> 0 | AS14: =NPA!AS14+NES!AS14+'2026-PKL NPA'!AS14+'2026- Harian NES'!AS14+'2026-Harian NPA'!AS14+'2026-LPK MKS NPA'!AS14+'2026-LPK MKM NPA'!AS14+'2026-LPK DKP NPA '!AS14+'2026-LPK CTPS NPA'!AS14+'2026-LPK CDB NPA'!AS14+'2026-OS CTPS NPA'!AS14+'2026-OS CDB NPA'!AS14 -> 0 | AT14: =AR14/$AR$24 -> #DIV/0! | AU14: =AS14/$AS$24 -> #DIV/0! | AV14: =NPA!AV14+NES!AV14+'2026-PKL NPA'!AV14+'2026- Harian NES'!AV14+'2026-Harian NPA'!AV14+'2026-LPK MKS NPA'!AV14+'2026-LPK MKM NPA'!AV14+'2026-LPK DKP NPA '!AV14+'2026-LPK CTPS NPA'!AV14+'2026-LPK CDB NPA'!AV14+'2026-OS CTPS NPA'!AV14+'2026-OS CDB NPA'!AV14 -> 0 | AW14: =NPA!AW14+NES!AW14+'2026-PKL NPA'!AW14+'2026- Harian NES'!AW14+'2026-Harian NPA'!AW14+'2026-LPK MKS NPA'!AW14+'2026-LPK MKM NPA'!AW14+'2026-LPK DKP NPA '!AW14+'2026-LPK CTPS NPA'!AW14+'2026-LPK CDB NPA'!AW14+'2026-OS CTPS NPA'!AW14+'2026-OS CDB NPA'!AW14 -> 0 | AX14: =AV14/$AJ$24 -> #DIV/0! | AY14: =AW14/$AK$24 -> #DIV/0! | AZ14: =E14+I14+M14+Q14+U14+Y14+AC14+AG14+AK14+AO14+AS14+AW14 -> 310753971 | BA14: =AVERAGE(F14,J14,N14,R14,V14,Z14,AD14,AH14,AL14,AP14,AT14,AX14) -> #DIV/0! | BB14: =AVERAGE(G14,K14,O14,S14,W14,AA14,AE14,AI14,AM14,AQ14,AU14,AY14) -> #DIV/0! | BC14: =E14+I14+M14 -> 310753971 | BD14: =Q14+U14+Y14 -> 0 | BE14: =AC14+AG14+AK14 -> 0 | BF14: =AO14+AS14+AW14 -> 0
